Workbook
Name FX_Rate_Entity1: FX_Conversion!$C$4
Name FX_Rate_Entity10: FX_Conversion!$C$13
Name FX_Rate_Entity2: FX_Conversion!$C$5
Name FX_Rate_Entity3: FX_Conversion!$C$6
Name FX_Rate_Entity4: FX_Conversion!$C$7
Name FX_Rate_Entity5: FX_Conversion!$C$8
Name FX_Rate_Entity6: FX_Conversion!$C$9
Name FX_Rate_Entity7: FX_Conversion!$C$10
Name FX_Rate_Entity8: FX_Conversion!$C$11
Name FX_Rate_Entity9: FX_Conversion!$C$12
Name NR_Beta: Valuation!$B$6
Name NR_Client_Currency: Client_Info!$B$6
Name NR_Client_Name: Client_Info!$B$3
Name NR_Cost_of_Debt: Valuation!$B$8
Name NR_Cost_of_Equity: Valuation!$B$12
Name NR_DCF_Value: Valuation!$B$23
Name NR_Debt_Weight: Valuation!$B$10
Name NR_EBITDA_Multiple: "Valuation!B27"
Name NR_EBITDA_Normalized: "Adjustments!B21"
Name NR_Entity_Count: Client_Info!$B$10
Name NR_Equity_Weight: Valuation!$B$11
Name NR_Exit_Multiple: "Valuation!C18"
Name NR_Final_Valuation: Valuation!$B$36
Name NR_FX_Auto: FX_Conversion!$J$8
Name NR_FX_Date: FX_Conversion!$J$6
Name NR_FX_Final: FX_Conversion!$J$9
Name NR_FX_Source: FX_Conversion!$J$5
Name NR_Industry: Client_Info!$B$4
Name NR_List_ContributionType: Client_Info!$N$2:$N$5
Name NR_List_Country: Client_Info!$J$2:$J$11
Name NR_List_Currency: Client_Info!$K$2:$K$11
Name NR_List_Document_Status: Client_Info!$O$8:$R$8
Name NR_List_DocumentStatus: Client_Info!$P$2:$P$4
Name NR_List_Entity: Client_Info!$O$11:$W$11
Name NR_List_FX_Source: Client_Info!$O$6:$P$6
Name NR_List_FXSource: Client_Info!$M$2:$M$3
Name NR_List_JV_Contribution_Type: Client_Info!$O$4:$R$4
Name NR_List_OverrideReason: Client_Info!$R$2:$R$4
Name NR_List_Ownership_Type: Client_Info!$O$3:$R$3
Name NR_List_Rate_Override_Reason: Client_Info!$O$7:$R$7
Name NR_List_Scenario: Client_Info!$O$9:$Q$9
Name NR_List_Waterfall_Tier: Client_Info!$O$5:$R$5
Name NR_List_WaterfallTier: Client_Info!$O$2:$O$5
Name NR_List_Yes_No: Client_Info!$O$10:$P$10
Name NR_List_YesNo: Client_Info!$L$2:$L$3
Name NR_Location: Client_Info!$B$5
Name NR_Market_Risk_Premium: Valuation!$B$7
Name NR_Multiples_Value: "Valuation!D30"
Name NR_PE_Multiple: "Valuation!B29"
Name NR_Revenue_Multiple: "Valuation!B28"
Name NR_RiskFree: Valuation!$B$5
Name NR_Service_Line: Client_Info!$B$8
Name NR_Tax_Rate: Valuation!$B$9
Name NR_Terminal_Growth: "Valuation!B18"
Name NR_Terminal_Value: "Valuation!G19"
Name NR_USD_Rate: FX_Conversion!$J$7
Name NR_Valuation_Date: Client_Info!$B$7
Name NR_Valuation_Type: Client_Info!$B$9
Name NR_WACC: Valuation!$B$13

Sheet Client_Info
A1: CLIENT INFORMATION FORM | J1: Country_List | K1: Currency_List | L1: YesNo_List | M1: FX_Source_List | N1: List_Country | O1: United States | P1: Canada | Q1: United Kingdom | R1: Germany | S1: France | T1: Japan | U1: Australia | V1: Mexico | W1: Entity 10
A2: Field | B2: Input | J2: United States | K2: USD | L2: Yes | M2: Auto | N2: List_Currency | O2: USD | P2: EUR | Q2: GBP | R2: CAD | S2: JPY | T2: AUD | U2: MXN | V2: CHF
A3: Client Name | J3: Canada | K3: EUR | L3: No | M3: Manual | N3: List_Ownership_Type | O3: Subsidiary | P3: JV | Q3: Minority | R3: Branch
A4: Industry (NAICS) | J4: United Kingdom | K4: GBP | N4: List_JV_Contribution_Type | O4: Cash | P4: IP | Q4: Services | R4: Assets
A5: Location | J5: Germany | K5: CAD | N5: List_Waterfall_Tier | O5: Tier 1 | P5: Tier 2 | Q5: Tier 3 | R5: Tier 4
A6: Client Currency | J6: France | K6: JPY | N6: List_FX_Source | O6: Auto | P6: Manual
A7: Valuation Date | J7: India | K7: AUD | N7: List_Rate_Override_Reason | O7: Manual Override | P7: Data Provider Exception | Q7: Historical Adjustment | R7: Management Input
A8: Service Line | J8: Japan | K8: INR | N8: List_Document_Status | O8: Received | P8: Missing | Q8: Requested | R8: Under Review
A9: Valuation Type | J9: Australia | K9: MXN | N9: List_Scenario | O9: Best Case | P9: Base Case | Q9: Worst Case
A10: Entity Count | B10: 10 | J10: Mexico | K10: BRL | N10: List_Yes_No | O10: Yes | P10: No
J11: Brazil | K11: CHF | N11: List_Entity | O11: Entity 1 | P11: Entity 2 | Q11: Entity 3 | R11: Entity 4 | S11: Entity 5 | T11: Entity 6 | U11: Entity 7 | V11: Entity 8

Sheet FX_Conversion
A1: FX CONVERSION - MULTI ENTITY | I1: FX CONTROL PANEL
A3: Entity | B3: Currency | C3: Previous Month-End FX Rate | D3: Source URL | E3: AI_Fetched (Yes/No) | F3: Manual Override (Yes/No) | G3: Notes | I3: Field | J3: Value
A4: Entity 1 | E4: =IF(OR(B4="",D4=""),"","Yes") | G4: =IF(B4="","WARNING: Missing Currency Data",IF(C4="","WARNING: Missing FX Rate","")) -> WARNING: Missing Currency Data | I4: Client Currency | J4: =IF(Client_Info!B6="","",Client_Info!B6)
A5: Entity 2 | E5: =IF(OR(B5="",D5=""),"","Yes") | G5: =IF(B5="","WARNING: Missing Currency Data",IF(C5="","WARNING: Missing FX Rate","")) -> WARNING: Missing Currency Data | I5: FX Rate Source
A6: Entity 3 | E6: =IF(OR(B6="",D6=""),"","Yes") | G6: =IF(B6="","WARNING: Missing Currency Data",IF(C6="","WARNING: Missing FX Rate","")) -> WARNING: Missing Currency Data | I6: FX Historical Date | J6: =EOMONTH(TODAY(),-1) -> 46142
A7: Entity 4 | E7: =IF(OR(B7="",D7=""),"","Yes") | G7: =IF(B7="","WARNING: Missing Currency Data",IF(C7="","WARNING: Missing FX Rate","")) -> WARNING: Missing Currency Data | I7: USD Conversion Rate
A8: Entity 5 | E8: =IF(OR(B8="",D8=""),"","Yes") | G8: =IF(B8="","WARNING: Missing Currency Data",IF(C8="","WARNING: Missing FX Rate","")) -> WARNING: Missing Currency Data | I8: Auto-Fetched FX Rate | J8: =IF($J$4="","",IFERROR(INDEX($C$4:$C$13,MATCH($J$4,$B$4:$B$13,0)),""))
A9: Entity 6 | E9: =IF(OR(B9="",D9=""),"","Yes") | G9: =IF(B9="","WARNING: Missing Currency Data",IF(C9="","WARNING: Missing FX Rate","")) -> WARNING: Missing Currency Data | I9: Final FX Rate Used | J9: =IF(NR_FX_Source="Manual",NR_USD_Rate,NR_FX_Auto)
A10: Entity 7 | E10: =IF(OR(B10="",D10=""),"","Yes") | G10: =IF(B10="","WARNING: Missing Currency Data",IF(C10="","WARNING: Missing FX Rate","")) -> WARNING: Missing Currency Data
A11: Entity 8 | E11: =IF(OR(B11="",D11=""),"","Yes") | G11: =IF(B11="","WARNING: Missing Currency Data",IF(C11="","WARNING: Missing FX Rate","")) -> WARNING: Missing Currency Data
A12: Entity 9 | E12: =IF(OR(B12="",D12=""),"","Yes") | G12: =IF(B12="","WARNING: Missing Currency Data",IF(C12="","WARNING: Missing FX Rate","")) -> WARNING: Missing Currency Data
A13: Entity 10 | E13: =IF(OR(B13="",D13=""),"","Yes") | G13: =IF(B13="","WARNING: Missing Currency Data",IF(C13="","WARNING: Missing FX Rate","")) -> WARNING: Missing Currency Data
A16: Formula Reference
A17: Code
A18: Value_USD = Value_Local * FX_Rate
A19: Policy | B19: All rate lookups must use previous month-end values with manual override allowed.
A20: Warning Rule | B20: If currency is missing, display a warning.

Sheet Fin_Inputs_Entity1
A1: ENTITY 1 FINANCIAL INPUTS
A3: INCOME STATEMENT
A4: Line Item | B4: Year 1 | C4: Year 2 | D4: Year 3 | E4: Year 4 | F4: Year 5
A5: Revenue
A6: COGS
A7: Gross Profit
A8: Operating Expenses
A9: EBITDA
A10: Depreciation
A11: EBIT
A12: Interest
A13: Taxes
A14: Net Income
A16: BALANCE SHEET
A17: Line Item | B17: Year 1 | C17: Year 2 | D17: Year 3 | E17: Year 4 | F17: Year 5
A18: Cash
A19: AR
A20: Inventory
A21: Current Assets
A22: PP&E
A23: Total Assets
A24: AP
A25: Accrued Liabilities
A26: Short-Term Debt
A27: Long-Term Debt
A28: Total Liabilities
A29: Equity
A31: CASH FLOW STATEMENT
A32: Line Item | B32: Year 1 | C32: Year 2 | D32: Year 3 | E32: Year 4 | F32: Year 5
A33: Net Income
A34: Depreciation
A35: Working Capital Changes
A36: Capex
A37: Free Cash Flow

Sheet Fin_Inputs_Entity2
A1: ENTITY 2 FINANCIAL INPUTS
A3: INCOME STATEMENT
A4: Line Item | B4: Year 1 | C4: Year 2 | D4: Year 3 | E4: Year 4 | F4: Year 5
A5: Revenue
A6: COGS
A7: Gross Profit
A8: Operating Expenses
A9: EBITDA
A10: Depreciation
A11: EBIT
A12: Interest
A13: Taxes
A14: Net Income
A16: BALANCE SHEET
A17: Line Item | B17: Year 1 | C17: Year 2 | D17: Year 3 | E17: Year 4 | F17: Year 5
A18: Cash
A19: AR
A20: Inventory
A21: Current Assets
A22: PP&E
A23: Total Assets
A24: AP
A25: Accrued Liabilities
A26: Short-Term Debt
A27: Long-Term Debt
A28: Total Liabilities
A29: Equity
A31: CASH FLOW STATEMENT
A32: Line Item | B32: Year 1 | C32: Year 2 | D32: Year 3 | E32: Year 4 | F32: Year 5
A33: Net Income
A34: Depreciation
A35: Working Capital Changes
A36: Capex
A37: Free Cash Flow

Sheet Fin_Inputs_Entity3
A1: ENTITY 3 FINANCIAL INPUTS
A3: INCOME STATEMENT
A4: Line Item | B4: Year 1 | C4: Year 2 | D4: Year 3 | E4: Year 4 | F4: Year 5
A5: Revenue
A6: COGS
A7: Gross Profit
A8: Operating Expenses
A9: EBITDA
A10: Depreciation
A11: EBIT
A12: Interest
A13: Taxes
A14: Net Income
A16: BALANCE SHEET
A17: Line Item | B17: Year 1 | C17: Year 2 | D17: Year 3 | E17: Year 4 | F17: Year 5
A18: Cash
A19: AR
A20: Inventory
A21: Current Assets
A22: PP&E
A23: Total Assets
A24: AP
A25: Accrued Liabilities
A26: Short-Term Debt
A27: Long-Term Debt
A28: Total Liabilities
A29: Equity
A31: CASH FLOW STATEMENT
A32: Line Item | B32: Year 1 | C32: Year 2 | D32: Year 3 | E32: Year 4 | F32: Year 5
A33: Net Income
A34: Depreciation
A35: Working Capital Changes
A36: Capex
A37: Free Cash Flow

Sheet Adjustments
A1: EBITDA ADJUSTMENTS
A3: SECTION 1: OWNER ADJUSTMENTS
A4: Adjustment Item | B4: Amount | C4: Notes
A5: Owner Salary Normalization
A6: Related Party Transactions
A7: Discretionary Expenses
A8: Subtotal Owner Adjustments | B8: =SUM(B5:B7) -> 0
A10: SECTION 2: NON RECURRING ITEMS
A11: Adjustment Item | B11: Amount | C11: Notes
A12: One Time Legal Fees
A13: Asset Write Offs
A14: Extraordinary Gains/Losses
A15: Subtotal Non Recurring | B15: =SUM(B12:B14) -> 0
A17: SECTION 3: NORMALIZED EBITDA
A18: Item | B18: Amount | C18: Source
A19: EBITDA (from Fin_Inputs) | B19: =Fin_Inputs_Entity1!F9 -> 0 | C19: Fin_Inputs_Entity1!F9
A20: Total Adjustments | B20: =B8+B15 -> 0 | C20: Sum of all adjustments
A21: Normalized EBITDA | B21: =B19+B20 -> 0 | C21: Normalized EBITDA = EBITDA + Total Adjustments

Sheet KPIs
A1: KEY PERFORMANCE INDICATORS
A3: KPI | B3: Formula | C3: Value | D3: Description
A4: Revenue CAGR | B4: {=(Year5/Year1)^(1/4)-1} -> #NAME? | C4: =IF(OR(Fin_Inputs_Entity1!B5=0,Fin_Inputs_Entity1!F5=0),"",(Fin_Inputs_Entity1!F5/Fin_Inputs_Entity1!B5)^(1/4)-1) | D4: 5-Year Compound Annual Growth Rate
A5: Gross Margin | B5: {=Gross Profit / Revenue} -> #NAME? | C5: =IF(Fin_Inputs_Entity1!F5=0,"",Fin_Inputs_Entity1!F7/Fin_Inputs_Entity1!F5) | D5: Profitability after COGS
A6: EBITDA Margin | B6: {=EBITDA / Revenue} -> #NAME? | C6: =IF(Fin_Inputs_Entity1!F5=0,"",Fin_Inputs_Entity1!F9/Fin_Inputs_Entity1!F5) | D6: Operating profitability
A7: Net Margin | B7: {=Net Income / Revenue} -> #NAME? | C7: =IF(Fin_Inputs_Entity1!F5=0,"",Fin_Inputs_Entity1!F14/Fin_Inputs_Entity1!F5) | D7: Bottom line profitability
A8: Working Capital Ratio | B8: {=(Current Assets-AP-Accrued Liabilities) / Revenue} -> #NAME? | C8: =IF(Fin_Inputs_Entity1!F5=0,"",(Fin_Inputs_Entity1!F21-Fin_Inputs_Entity1!F24-Fin_Inputs_Entity1!F25)/Fin_Inputs_Entity1!F5) | D8: WC as % of Revenue
A9: Current Ratio | B9: {=Current Assets / (AP + Accrued Liabilities + Short-Term Debt)} -> #NAME? | C9: =IF((Fin_Inputs_Entity1!F24+Fin_Inputs_Entity1!F25+Fin_Inputs_Entity1!F26)=0,"",Fin_Inputs_Entity1!F21/(Fin_Inputs_Entity1!F24+Fin_Inputs_Entity1!F25+Fin_Inputs_Entity1!F26)) | D9: Short-term liquidity
A10: Quick Ratio | B10: {=(Current Assets-Inventory) / (AP + Accrued Liabilities + Short-Term Debt)} -> #NAME? | C10: =IF((Fin_Inputs_Entity1!F24+Fin_Inputs_Entity1!F25+Fin_Inputs_Entity1!F26)=0,"",(Fin_Inputs_Entity1!F21-Fin_Inputs_Entity1!F20)/(Fin_Inputs_Entity1!F24+Fin_Inputs_Entity1!F25+Fin_Inputs_Entity1!F26)) | D10: Liquidity excl. inventory
A11: Debt/EBITDA | B11: {=Total Debt / EBITDA} -> #NAME? | C11: =IF(Fin_Inputs_Entity1!F9=0,"",(Fin_Inputs_Entity1!F26+Fin_Inputs_Entity1!F27)/Fin_Inputs_Entity1!F9) | D11: Leverage ratio
A12: Interest Coverage | B12: {=EBIT / Interest} -> #NAME? | C12: =IF(Fin_Inputs_Entity1!F12=0,"",Fin_Inputs_Entity1!F11/Fin_Inputs_Entity1!F12) | D12: Ability to service debt
A13: ROA | B13: {=Net Income / Total Assets} -> #NAME? | C13: =IF(Fin_Inputs_Entity1!F23=0,"",Fin_Inputs_Entity1!F14/Fin_Inputs_Entity1!F23) | D13: Return on Assets
A14: ROE | B14: {=Net Income / Equity} -> #NAME? | C14: =IF(Fin_Inputs_Entity1!F29=0,"",Fin_Inputs_Entity1!F14/Fin_Inputs_Entity1!F29) | D14: Return on Equity

Sheet Valuation
A1: VALUATION ANALYSIS
A3: SECTION A: WACC INPUTS
A4: Input | B4: Value | C4: Notes
A5: Risk Free Rate | B5: =Valuation_Entity1!B5 | C5: 10-Year Treasury
A6: Beta | B6: =Valuation_Entity1!B6 | C6: Industry/Company Beta
A7: Market Risk Premium | B7: =Valuation_Entity1!B7 | C7: Equity Risk Premium
A8: Cost of Debt | B8: =Valuation_Entity1!B8 | C8: Pre-tax cost
A9: Tax Rate | B9: =Valuation_Entity1!B9 | C9: Effective tax rate
A10: Debt Weight | B10: =Valuation_Entity1!B10 | C10: D/(D+E)
A11: Equity Weight | B11: =Valuation_Entity1!B11 | C11: E/(D+E)
A12: Cost of Equity | B12: =Valuation_Entity1!B12 | C12: Cost_of_Equity = Risk_Free_Rate + Beta * Market_Risk_Premium
A13: WACC | B13: =Valuation_Entity1!B13 | C13: Weighted Average
A15: SECTION B: DCF MODEL
A16: Item | B16: Year 1 | C16: Year 2 | D16: Year 3 | E16: Year 4 | F16: Year 5 | G16: Terminal
A17: Forecasted FCF | B17: =Valuation_Entity1!B18 | C17: =Valuation_Entity1!C18 | D17: =Valuation_Entity1!D18 | E17: =Valuation_Entity1!E18 | F17: =Valuation_Entity1!F18
A18: Terminal Growth Rate | B18: =Valuation_Entity1!B19 -> 0.02
A19: Terminal Value | G19: =Valuation_Entity1!G19
A20: Discount Factor | B20: =Valuation_Entity1!B20 | C20: =Valuation_Entity1!C20 | D20: =Valuation_Entity1!D20 | E20: =Valuation_Entity1!E20 | F20: =Valuation_Entity1!F20 | G20: =Valuation_Entity1!G20
A21: PV of Cash Flows | B21: =Valuation_Entity1!B21 | C21: =Valuation_Entity1!C21 | D21: =Valuation_Entity1!D21 | E21: =Valuation_Entity1!E21 | F21: =Valuation_Entity1!F21 | G21: =Valuation_Entity1!G21
A23: DCF Enterprise Value | B23: =Valuation_Entity1!B22
A25: SECTION C: MARKET MULTIPLES
A26: Multiple | B26: Multiple Value | C26: Metric | D26: Implied EV
A27: EV/EBITDA | B27: =Valuation_Entity1!B27 -> 6 | C27: =Valuation_Entity1!C27 | D27: =Valuation_Entity1!D27
A28: EV/Revenue | B28: =Valuation_Entity1!B28 -> 1.5 | C28: =Valuation_Entity1!C28 | D28: =Valuation_Entity1!D28
A29: P/E | B29: =Valuation_Entity1!B29 -> 10 | C29: =Valuation_Entity1!C29 | D29: =Valuation_Entity1!D29
A30: Average Multiples Value | D30: =Valuation_Entity1!B30
A32: SECTION D: FINAL VALUATION
A33: Valuation Method | B33: Value | C33: Weight
A34: DCF Value | B34: =Valuation_Entity1!B34 | C34: 0.5
A35: Market Multiples Value | B35: =Valuation_Entity1!B35 | C35: 0.5
A36: Final Valuation | B36: =Valuation_Entity1!B37

Sheet Model_3Statement
A1: 3-STATEMENT FINANCIAL MODEL
A3: REVENUE MODEL
A4: Item | B4: Historical | C4: Year 1 | D4: Year 2 | E4: Year 3 | F4: Year 4 | G4: Year 5
A5: Base Revenue | B5: =Fin_Inputs_Entity1!B5 -> 0
A6: Growth Rate
A7: Projected Revenue | B7: =IF(B5>0,B5*(1+B6),0) -> 0 | C7: =IF(B7>0,B7*(1+C6),0) -> 0 | D7: =IF(C7>0,C7*(1+D6),0) -> 0 | E7: =IF(D7>0,D7*(1+E6),0) -> 0 | F7: =IF(E7>0,E7*(1+F6),0) -> 0 | G7: =IF(F7>0,F7*(1+G6),0) -> 0
A9: COGS MODEL
A10: Item | B10: Historical | C10: Year 1 | D10: Year 2 | E10: Year 3 | F10: Year 4 | G10: Year 5
A11: COGS % of Revenue
A12: Projected COGS | B12: =B7*B11 -> 0 | C12: =C7*C11 -> 0 | D12: =D7*D11 -> 0 | E12: =E7*E11 -> 0 | F12: =F7*F11 -> 0 | G12: =G7*G11 -> 0
A13: Gross Profit | B13: =B7-B12 -> 0 | C13: =C7-C12 -> 0 | D13: =D7-D12 -> 0 | E13: =E7-E12 -> 0 | F13: =F7-F12 -> 0 | G13: =G7-G12 -> 0
A15: OPERATING EXPENSE MODEL
A16: Item | B16: Historical | C16: Year 1 | D16: Year 2 | E16: Year 3 | F16: Year 4 | G16: Year 5
A17: OpEx % of Revenue
A18: Projected OpEx | B18: =B7*B17 -> 0 | C18: =C7*C17 -> 0 | D18: =D7*D17 -> 0 | E18: =E7*E17 -> 0 | F18: =F7*F17 -> 0 | G18: =G7*G17 -> 0
A19: EBITDA | B19: =B13-B18 -> 0 | C19: =C13-C18 -> 0 | D19: =D13-D18 -> 0 | E19: =E13-E18 -> 0 | F19: =F13-F18 -> 0 | G19: =G13-G18 -> 0
A21: WORKING CAPITAL SCHEDULE
A22: Item | B22: Historical | C22: Year 1 | D22: Year 2 | E22: Year 3 | F22: Year 4 | G22: Year 5
A23: AR Days
A24: Inventory Days
A25: AP Days
A26: Accounts Receivable | B26: =IFERROR(B7*B23/365,0) -> 0 | C26: =IFERROR(C7*C23/365,0) -> 0 | D26: =IFERROR(D7*D23/365,0) -> 0 | E26: =IFERROR(E7*E23/365,0) -> 0 | F26: =IFERROR(F7*F23/365,0) -> 0 | G26: =IFERROR(G7*G23/365,0) -> 0
A27: Inventory | B27: =IFERROR(B12*B24/365,0) -> 0 | C27: =IFERROR(C12*C24/365,0) -> 0 | D27: =IFERROR(D12*D24/365,0) -> 0 | E27: =IFERROR(E12*E24/365,0) -> 0 | F27: =IFERROR(F12*F24/365,0) -> 0 | G27: =IFERROR(G12*G24/365,0) -> 0
A28: Accounts Payable | B28: =IFERROR(B12*B25/365,0) -> 0 | C28: =IFERROR(C12*C25/365,0) -> 0 | D28: =IFERROR(D12*D25/365,0) -> 0 | E28: =IFERROR(E12*E25/365,0) -> 0 | F28: =IFERROR(F12*F25/365,0) -> 0 | G28: =IFERROR(G12*G25/365,0) -> 0
A29: Net Working Capital | B29: =B26+B27-B28 -> 0 | C29: =C26+C27-C28 -> 0 | D29: =D26+D27-D28 -> 0 | E29: =E26+E27-E28 -> 0 | F29: =F26+F27-F28 -> 0 | G29: =G26+G27-G28 -> 0
A30: Change in NWC | C30: =C29-B29 -> 0 | D30: =D29-C29 -> 0 | E30: =E29-D29 -> 0 | F30: =F29-E29 -> 0 | G30: =G29-F29 -> 0
A32: CAPEX SCHEDULE
A33: Item | B33: Historical | C33: Year 1 | D33: Year 2 | E33: Year 3 | F33: Year 4 | G33: Year 5
A34: Capex % of Revenue
A35: Capital Expenditures | B35: =B7*B34 -> 0 | C35: =C7*C34 -> 0 | D35: =D7*D34 -> 0 | E35: =E7*E34 -> 0 | F35: =F7*F34 -> 0 | G35: =G7*G34 -> 0
A37: DEPRECIATION SCHEDULE
A38: Item | B38: Historical | C38: Year 1 | D38: Year 2 | E38: Year 3 | F38: Year 4 | G38: Year 5
A39: D&A % of Revenue
A40: Depreciation | B40: =B7*B39 -> 0 | C40: =C7*C39 -> 0 | D40: =D7*D39 -> 0 | E40: =E7*E39 -> 0 | F40: =F7*F39 -> 0 | G40: =G7*G39 -> 0
A41: EBIT | B41: =B19-B40 -> 0 | C41: =C19-C40 -> 0 | D41: =D19-D40 -> 0 | E41: =E19-E40 -> 0 | F41: =F19-F40 -> 0 | G41: =G19-G40 -> 0
A43: DEBT SCHEDULE
A44: Item | B44: Historical | C44: Year 1 | D44: Year 2 | E44: Year 3 | F44: Year 4 | G44: Year 5
A45: Beginning Debt | C45: =B48 -> 0 | D45: =C48 -> 0 | E45: =D48 -> 0 | F45: =E48 -> 0 | G45: =F48 -> 0
A46: New Borrowings
A47: Repayments
...

Sheet Charts
A1: CHARTS & VISUALIZATIONS
A3: CHART DATA
A5: Revenue Growth | B5: Year 1 | C5: Year 2 | D5: Year 3 | E5: Year 4 | F5: Year 5
A6: Revenue | B6: =Fin_Inputs_Entity1!B5 -> 0 | C6: =Fin_Inputs_Entity1!C5 -> 0 | D6: =Fin_Inputs_Entity1!D5 -> 0 | E6: =Fin_Inputs_Entity1!E5 -> 0 | F6: =Fin_Inputs_Entity1!F5 -> 0
A7: YoY Growth % | C7: =IFERROR((C6-B6)/B6,0) -> 0 | D7: =IFERROR((D6-C6)/C6,0) -> 0 | E7: =IFERROR((E6-D6)/D6,0) -> 0 | F7: =IFERROR((F6-E6)/E6,0) -> 0
A9: EBITDA Margin | B9: Year 1 | C9: Year 2 | D9: Year 3 | E9: Year 4 | F9: Year 5
A10: EBITDA | B10: =Fin_Inputs_Entity1!B9 -> 0 | C10: =Fin_Inputs_Entity1!C9 -> 0 | D10: =Fin_Inputs_Entity1!D9 -> 0 | E10: =Fin_Inputs_Entity1!E9 -> 0 | F10: =Fin_Inputs_Entity1!F9 -> 0
A11: Margin % | B11: =IFERROR(B10/B6,0) -> 0 | C11: =IFERROR(C10/C6,0) -> 0 | D11: =IFERROR(D10/D6,0) -> 0 | E11: =IFERROR(E10/E6,0) -> 0 | F11: =IFERROR(F10/F6,0) -> 0
A13: Cash Flow Trends | B13: Year 1 | C13: Year 2 | D13: Year 3 | E13: Year 4 | F13: Year 5
A14: Free Cash Flow | B14: =Fin_Inputs_Entity1!B37 -> 0 | C14: =Fin_Inputs_Entity1!C37 -> 0 | D14: =Fin_Inputs_Entity1!D37 -> 0 | E14: =Fin_Inputs_Entity1!E37 -> 0 | F14: =Fin_Inputs_Entity1!F37 -> 0
A16: Working Capital | B16: Year 1 | C16: Year 2 | D16: Year 3 | E16: Year 4 | F16: Year 5
A17: Current Assets | B17: =Fin_Inputs_Entity1!B21 -> 0 | C17: =Fin_Inputs_Entity1!C21 -> 0 | D17: =Fin_Inputs_Entity1!D21 -> 0 | E17: =Fin_Inputs_Entity1!E21 -> 0 | F17: =Fin_Inputs_Entity1!F21 -> 0
A18: Current Liabilities | B18: =SUM(Fin_Inputs_Entity1!B24:B26) -> 0 | C18: =SUM(Fin_Inputs_Entity1!C24:C26) -> 0 | D18: =SUM(Fin_Inputs_Entity1!D24:D26) -> 0 | E18: =SUM(Fin_Inputs_Entity1!E24:E26) -> 0 | F18: =SUM(Fin_Inputs_Entity1!F24:F26) -> 0
A19: Net WC | B19: =B17-B18 -> 0 | C19: =C17-C18 -> 0 | D19: =D17-D18 -> 0 | E19: =E17-E18 -> 0 | F19: =F17-F18 -> 0
A21: Valuation Summary | B21: DCF | C21: Multiples | D21: Final
A22: Value | B22: =NR_DCF_Value | C22: =NR_Multiples_Value -> Valuation!D30 | D22: =NR_Final_Valuation
A24: Benchmark Comparison | B24: Client | C24: Industry | D24: Variance
A25: EBITDA Margin | B25: =KPIs!C6 | C25: =Benchmarking!C5 -> 0 | D25: =B25-C25 -> #VALUE!
A26: Net Margin | B26: =KPIs!C7 | C26: =Benchmarking!C6 -> 0 | D26: =B26-C26 -> #VALUE!
A27: Revenue Growth | B27: =KPIs!C4 | C27: =Benchmarking!C4 -> 0 | D27: =B27-C27 -> #VALUE!
A29: Note: Charts will be created using the data above. Select data ranges and insert charts as needed.

Sheet Benchmarking
A1: INDUSTRY BENCHMARKING
A3: Metric | B3: Client | C3: Industry Average | D3: Variance
A4: Revenue Growth | B4: =KPIs!C4 | D4: =IFERROR(B4-C4,0) -> 0
A5: EBITDA Margin | B5: =KPIs!C6 | D5: =IFERROR(B5-C5,0) -> 0
A6: Net Margin | B6: =KPIs!C7 | D6: =IFERROR(B6-C6,0) -> 0
A7: Leverage (Debt/EBITDA) | B7: =KPIs!C11 | D7: =IFERROR(B7-C7,0) -> 0
A8: Working Capital % | B8: =KPIs!C8 | D8: =IFERROR(B8-C8,0) -> 0
A10: Instructions: Enter industry average benchmarks in yellow cells (Column C).

Sheet Due_Diligence
A1: DUE DILIGENCE ANALYSIS
A3: REVENUE TESTING
A4: Test Item | B4: Expected | C4: Actual | D4: Variance | E4: Notes
A5: Revenue per Customer | D5: =IFERROR(C5-B5,0) -> 0
A6: Customer Count Verification | D6: =IFERROR(C6-B6,0) -> 0
A7: Contract Value Reconciliation | D7: =IFERROR(C7-B7,0) -> 0
A8: Revenue Recognition Review | D8: =IFERROR(C8-B8,0) -> 0
A10: EXPENSE TESTING
A11: Test Item | B11: Expected | C11: Actual | D11: Variance | E11: Notes
A12: Payroll Verification | D12: =IFERROR(C12-B12,0) -> 0
A13: Vendor Payment Analysis | D13: =IFERROR(C13-B13,0) -> 0
A14: Related Party Expenses | D14: =IFERROR(C14-B14,0) -> 0
A15: One-Time vs Recurring | D15: =IFERROR(C15-B15,0) -> 0
A17: VARIANCE ANALYSIS
A18: Item | B18: Prior Year | C18: Current Year | D18: Variance % | E18: Explanation
A19: Revenue | D19: =IFERROR((C19-B19)/B19,0) -> 0
A20: Gross Profit | D20: =IFERROR((C20-B20)/B20,0) -> 0
A21: EBITDA | D21: =IFERROR((C21-B21)/B21,0) -> 0
A22: Net Income | D22: =IFERROR((C22-B22)/B22,0) -> 0
A24: RED FLAG IDENTIFICATION
A25: Red Flag Item | B25: Severity | C25: Amount | D25: Status | E25: Resolution
A26: Customer Concentration
A27: Related Party Issues
A28: Revenue Quality Concerns
A29: Working Capital Anomalies
A30: Contingent Liabilities
A32: NORMALIZATION SUMMARY
A33: Adjustment | B33: Amount | C33: Recurring? | D33: Impact | E33: Documentation
A34: Reported EBITDA | B34: =Fin_Inputs_Entity1!F9 -> 0
A35: Owner Comp Adjustment | B35: =Adjustments!B5 -> 0
A36: Related Party Adjustment | B36: =Adjustments!B6 -> 0
A37: Non-Recurring Items | B37: =Adjustments!B15 -> 0
A38: Normalized EBITDA | B38: =NR_EBITDA_Normalized -> Adjustments!B21

Sheet Deal_Terms
A1: M&A / JV DEAL TERMS
A3: OWNERSHIP PERCENTAGES
A4: Party | B4: Ownership % | C4: Notes
A5: Buyer/Investor 1
A6: Buyer/Investor 2
A7: Seller/Existing Owner
A8: Management Pool
A9: Total | B9: =SUM(B5:B8) -> 0 | C9: Must equal 100%
A11: PURCHASE PRICE
A12: Component | B12: Amount | C12: Notes
A13: Base Purchase Price
A14: Working Capital Adjustment
A15: Debt Assumption
A16: Cash on Hand
A17: Total Enterprise Value | B17: =B13+B14+B15-B16 -> 0
A19: EARN OUT STRUCTURE
A20: Milestone | B20: Target | C20: Payout
A21: Year 1 Revenue Target
A22: Year 2 Revenue Target
A23: Year 1 EBITDA Target
A24: Year 2 EBITDA Target
A25: Total Potential Earn Out | C25: =SUM(C21:C24) -> 0
A27: CONTRIBUTION AMOUNTS
A28: Party | B28: Cash | C28: Assets/Services
A29: Party 1
A30: Party 2
A31: Party 3
A32: Total Contributions | B32: =SUM(B29:B31) -> 0 | C32: =SUM(C29:C31) -> 0
A34: SYNERGIES
A35: Synergy Type | B35: Annual Amount | C35: Notes
A36: Revenue Synergies
A37: Cost Synergies
A38: Operational Efficiencies
A39: Total Synergies | B39: =SUM(B36:B38) -> 0
A41: SPECIAL RIGHTS
A42: Right/Provision | B42: Holder | C42: Details
A43: Board Seats
A44: Veto Rights
A45: Tag-Along Rights
A46: Drag-Along Rights
...

Sheet Consolidation
A1: CONSOLIDATION - 10 ENTITIES
A3: Metric | B3: Entity 1 | C3: Entity 2 | D3: Entity 3 | E3: Entity 4 | F3: Entity 5 | G3: Entity 6 | H3: Entity 7 | I3: Entity 8 | J3: Entity 9 | K3: Entity 10 | L3: Combined Total
A4: Combined Revenue | B4: =IF(FX_Rate_Entity1="","",N(Fin_Inputs_Entity1!F5)*FX_Rate_Entity1*IF(Entity_Ownership!C4="",1,Entity_Ownership!C4)) | C4: =IF(FX_Rate_Entity2="","",N(Fin_Inputs_Entity2!F5)*FX_Rate_Entity2*IF(Entity_Ownership!C5="",1,Entity_Ownership!C5)) | D4: =IF(FX_Rate_Entity3="","",N(Fin_Inputs_Entity3!F5)*FX_Rate_Entity3*IF(Entity_Ownership!C6="",1,Entity_Ownership!C6)) | E4: =IF(FX_Rate_Entity4="","",N(Fin_Inputs_Entity4!F5)*FX_Rate_Entity4*IF(Entity_Ownership!C7="",1,Entity_Ownership!C7)) | F4: =IF(FX_Rate_Entity5="","",N(Fin_Inputs_Entity5!F5)*FX_Rate_Entity5*IF(Entity_Ownership!C8="",1,Entity_Ownership!C8)) | G4: =IF(FX_Rate_Entity6="","",N(Fin_Inputs_Entity6!F5)*FX_Rate_Entity6*IF(Entity_Ownership!C9="",1,Entity_Ownership!C9)) | H4: =IF(FX_Rate_Entity7="","",N(Fin_Inputs_Entity7!F5)*FX_Rate_Entity7*IF(Entity_Ownership!C10="",1,Entity_Ownership!C10)) | I4: =IF(FX_Rate_Entity8="","",N(Fin_Inputs_Entity8!F5)*FX_Rate_Entity8*IF(Entity_Ownership!C11="",1,Entity_Ownership!C11)) | J4: =IF(FX_Rate_Entity9="","",N(Fin_Inputs_Entity9!F5)*FX_Rate_Entity9*IF(Entity_Ownership!C12="",1,Entity_Ownership!C12)) | K4: =IF(FX_Rate_Entity10="","",N(Fin_Inputs_Entity10!F5)*FX_Rate_Entity10*IF(Entity_Ownership!C13="",1,Entity_Ownership!C13)) | L4: =SUM(B4:K4) -> 0
A5: Combined EBITDA | B5: =IF(FX_Rate_Entity1="","",N(Fin_Inputs_Entity1!F9)*FX_Rate_Entity1*IF(Entity_Ownership!C4="",1,Entity_Ownership!C4)) | C5: =IF(FX_Rate_Entity2="","",N(Fin_Inputs_Entity2!F9)*FX_Rate_Entity2*IF(Entity_Ownership!C5="",1,Entity_Ownership!C5)) | D5: =IF(FX_Rate_Entity3="","",N(Fin_Inputs_Entity3!F9)*FX_Rate_Entity3*IF(Entity_Ownership!C6="",1,Entity_Ownership!C6)) | E5: =IF(FX_Rate_Entity4="","",N(Fin_Inputs_Entity4!F9)*FX_Rate_Entity4*IF(Entity_Ownership!C7="",1,Entity_Ownership!C7)) | F5: =IF(FX_Rate_Entity5="","",N(Fin_Inputs_Entity5!F9)*FX_Rate_Entity5*IF(Entity_Ownership!C8="",1,Entity_Ownership!C8)) | G5: =IF(FX_Rate_Entity6="","",N(Fin_Inputs_Entity6!F9)*FX_Rate_Entity6*IF(Entity_Ownership!C9="",1,Entity_Ownership!C9)) | H5: =IF(FX_Rate_Entity7="","",N(Fin_Inputs_Entity7!F9)*FX_Rate_Entity7*IF(Entity_Ownership!C10="",1,Entity_Ownership!C10)) | I5: =IF(FX_Rate_Entity8="","",N(Fin_Inputs_Entity8!F9)*FX_Rate_Entity8*IF(Entity_Ownership!C11="",1,Entity_Ownership!C11)) | J5: =IF(FX_Rate_Entity9="","",N(Fin_Inputs_Entity9!F9)*FX_Rate_Entity9*IF(Entity_Ownership!C12="",1,Entity_Ownership!C12)) | K5: =IF(FX_Rate_Entity10="","",N(Fin_Inputs_Entity10!F9)*FX_Rate_Entity10*IF(Entity_Ownership!C13="",1,Entity_Ownership!C13)) | L5: =SUM(B5:K5) -> 0
A6: Combined Cash Flow | B6: =IF(FX_Rate_Entity1="","",N(Fin_Inputs_Entity1!F37)*FX_Rate_Entity1*IF(Entity_Ownership!C4="",1,Entity_Ownership!C4)) | C6: =IF(FX_Rate_Entity2="","",N(Fin_Inputs_Entity2!F37)*FX_Rate_Entity2*IF(Entity_Ownership!C5="",1,Entity_Ownership!C5)) | D6: =IF(FX_Rate_Entity3="","",N(Fin_Inputs_Entity3!F37)*FX_Rate_Entity3*IF(Entity_Ownership!C6="",1,Entity_Ownership!C6)) | E6: =IF(FX_Rate_Entity4="","",N(Fin_Inputs_Entity4!F37)*FX_Rate_Entity4*IF(Entity_Ownership!C7="",1,Entity_Ownership!C7)) | F6: =IF(FX_Rate_Entity5="","",N(Fin_Inputs_Entity5!F37)*FX_Rate_Entity5*IF(Entity_Ownership!C8="",1,Entity_Ownership!C8)) | G6: =IF(FX_Rate_Entity6="","",N(Fin_Inputs_Entity6!F37)*FX_Rate_Entity6*IF(Entity_Ownership!C9="",1,Entity_Ownership!C9)) | H6: =IF(FX_Rate_Entity7="","",N(Fin_Inputs_Entity7!F37)*FX_Rate_Entity7*IF(Entity_Ownership!C10="",1,Entity_Ownership!C10)) | I6: =IF(FX_Rate_Entity8="","",N(Fin_Inputs_Entity8!F37)*FX_Rate_Entity8*IF(Entity_Ownership!C11="",1,Entity_Ownership!C11)) | J6: =IF(FX_Rate_Entity9="","",N(Fin_Inputs_Entity9!F37)*FX_Rate_Entity9*IF(Entity_Ownership!C12="",1,Entity_Ownership!C12)) | K6: =IF(FX_Rate_Entity10="","",N(Fin_Inputs_Entity10!F37)*FX_Rate_Entity10*IF(Entity_Ownership!C13="",1,Entity_Ownership!C13)) | L6: =SUM(B6:K6) -> 0
A7: Combined Debt | B7: =IF(FX_Rate_Entity1="","",(N(Fin_Inputs_Entity1!F26)+N(Fin_Inputs_Entity1!F27))*FX_Rate_Entity1*IF(Entity_Ownership!C4="",1,Entity_Ownership!C4)) | C7: =IF(FX_Rate_Entity2="","",(N(Fin_Inputs_Entity2!F26)+N(Fin_Inputs_Entity2!F27))*FX_Rate_Entity2*IF(Entity_Ownership!C5="",1,Entity_Ownership!C5)) | D7: =IF(FX_Rate_Entity3="","",(N(Fin_Inputs_Entity3!F26)+N(Fin_Inputs_Entity3!F27))*FX_Rate_Entity3*IF(Entity_Ownership!C6="",1,Entity_Ownership!C6)) | E7: =IF(FX_Rate_Entity4="","",(N(Fin_Inputs_Entity4!F26)+N(Fin_Inputs_Entity4!F27))*FX_Rate_Entity4*IF(Entity_Ownership!C7="",1,Entity_Ownership!C7)) | F7: =IF(FX_Rate_Entity5="","",(N(Fin_Inputs_Entity5!F26)+N(Fin_Inputs_Entity5!F27))*FX_Rate_Entity5*IF(Entity_Ownership!C8="",1,Entity_Ownership!C8)) | G7: =IF(FX_Rate_Entity6="","",(N(Fin_Inputs_Entity6!F26)+N(Fin_Inputs_Entity6!F27))*FX_Rate_Entity6*IF(Entity_Ownership!C9="",1,Entity_Ownership!C9)) | H7: =IF(FX_Rate_Entity7="","",(N(Fin_Inputs_Entity7!F26)+N(Fin_Inputs_Entity7!F27))*FX_Rate_Entity7*IF(Entity_Ownership!C10="",1,Entity_Ownership!C10)) | I7: =IF(FX_Rate_Entity8="","",(N(Fin_Inputs_Entity8!F26)+N(Fin_Inputs_Entity8!F27))*FX_Rate_Entity8*IF(Entity_Ownership!C11="",1,Entity_Ownership!C11)) | J7: =IF(FX_Rate_Entity9="","",(N(Fin_Inputs_Entity9!F26)+N(Fin_Inputs_Entity9!F27))*FX_Rate_Entity9*IF(Entity_Ownership!C12="",1,Entity_Ownership!C12)) | K7: =IF(FX_Rate_Entity10="","",(N(Fin_Inputs_Entity10!F26)+N(Fin_Inputs_Entity10!F27))*FX_Rate_Entity10*IF(Entity_Ownership!C13="",1,Entity_Ownership!C13)) | L7: =SUM(B7:K7) -> 0
A8: Combined Working Capital | B8: =IF(FX_Rate_Entity1="","",(N(Fin_Inputs_Entity1!F21)-N(Fin_Inputs_Entity1!F24)-N(Fin_Inputs_Entity1!F25))*FX_Rate_Entity1*IF(Entity_Ownership!C4="",1,Entity_Ownership!C4)) | C8: =IF(FX_Rate_Entity2="","",(N(Fin_Inputs_Entity2!F21)-N(Fin_Inputs_Entity2!F24)-N(Fin_Inputs_Entity2!F25))*FX_Rate_Entity2*IF(Entity_Ownership!C5="",1,Entity_Ownership!C5)) | D8: =IF(FX_Rate_Entity3="","",(N(Fin_Inputs_Entity3!F21)-N(Fin_Inputs_Entity3!F24)-N(Fin_Inputs_Entity3!F25))*FX_Rate_Entity3*IF(Entity_Ownership!C6="",1,Entity_Ownership!C6)) | E8: =IF(FX_Rate_Entity4="","",(N(Fin_Inputs_Entity4!F21)-N(Fin_Inputs_Entity4!F24)-N(Fin_Inputs_Entity4!F25))*FX_Rate_Entity4*IF(Entity_Ownership!C7="",1,Entity_Ownership!C7)) | F8: =IF(FX_Rate_Entity5="","",(N(Fin_Inputs_Entity5!F21)-N(Fin_Inputs_Entity5!F24)-N(Fin_Inputs_Entity5!F25))*FX_Rate_Entity5*IF(Entity_Ownership!C8="",1,Entity_Ownership!C8)) | G8: =IF(FX_Rate_Entity6="","",(N(Fin_Inputs_Entity6!F21)-N(Fin_Inputs_Entity6!F24)-N(Fin_Inputs_Entity6!F25))*FX_Rate_Entity6*IF(Entity_Ownership!C9="",1,Entity_Ownership!C9)) | H8: =IF(FX_Rate_Entity7="","",(N(Fin_Inputs_Entity7!F21)-N(Fin_Inputs_Entity7!F24)-N(Fin_Inputs_Entity7!F25))*FX_Rate_Entity7*IF(Entity_Ownership!C10="",1,Entity_Ownership!C10)) | I8: =IF(FX_Rate_Entity8="","",(N(Fin_Inputs_Entity8!F21)-N(Fin_Inputs_Entity8!F24)-N(Fin_Inputs_Entity8!F25))*FX_Rate_Entity8*IF(Entity_Ownership!C11="",1,Entity_Ownership!C11)) | J8: =IF(FX_Rate_Entity9="","",(N(Fin_Inputs_Entity9!F21)-N(Fin_Inputs_Entity9!F24)-N(Fin_Inputs_Entity9!F25))*FX_Rate_Entity9*IF(Entity_Ownership!C12="",1,Entity_Ownership!C12)) | K8: =IF(FX_Rate_Entity10="","",(N(Fin_Inputs_Entity10!F21)-N(Fin_Inputs_Entity10!F24)-N(Fin_Inputs_Entity10!F25))*FX_Rate_Entity10*IF(Entity_Ownership!C13="",1,Entity_Ownership!C13)) | L8: =SUM(B8:K8) -> 0
A9: Combined Valuation | B9: =Valuation_Entity1!B37 | C9: =Valuation_Entity2!B37 | D9: =Valuation_Entity3!B37 | E9: =Valuation_Entity4!B37 | F9: =Valuation_Entity5!B37 | G9: =Valuation_Entity6!B37 | H9: =Valuation_Entity7!B37 | I9: =Valuation_Entity8!B37 | J9: =Valuation_Entity9!B37 | K9: =Valuation_Entity10!B37 | L9: =SUM(B9:K9) -> 0
A10: Combined Loan Readiness Metrics | B10: =Loan_Readiness!D11 | C10: =Loan_Readiness!D12 | D10: =Loan_Readiness!D13 | E10: =Loan_Readiness!D14 | F10: =Loan_Readiness!D15 | G10: =Loan_Readiness!D16 | H10: =Loan_Readiness!D17 | I10: =Loan_Readiness!D18 | J10: =Loan_Readiness!D19 | K10: =Loan_Readiness!D20 | L10: =IF(COUNT(B10:K10)=0,"",AVERAGE(B10:K10))
A11: Warning | B11: =IF(COUNT(Fin_Inputs_Entity1!B5:F37)=0,"WARNING: Missing Financial Data",IF(OR(FX_Conversion!B4="",Entity_Ownership!F4="",Entity_Ownership!G4=""),"WARNING: Missing Setup Data","")) -> WARNING: Missing Financial Data | C11: =IF(COUNT(Fin_Inputs_Entity2!B5:F37)=0,"WARNING: Missing Financial Data",IF(OR(FX_Conversion!B5="",Entity_Ownership!F5="",Entity_Ownership!G5=""),"WARNING: Missing Setup Data","")) -> WARNING: Missing Financial Data | D11: =IF(COUNT(Fin_Inputs_Entity3!B5:F37)=0,"WARNING: Missing Financial Data",IF(OR(FX_Conversion!B6="",Entity_Ownership!F6="",Entity_Ownership!G6=""),"WARNING: Missing Setup Data","")) -> WARNING: Missing Financial Data | E11: =IF(COUNT(Fin_Inputs_Entity4!B5:F37)=0,"WARNING: Missing Financial Data",IF(OR(FX_Conversion!B7="",Entity_Ownership!F7="",Entity_Ownership!G7=""),"WARNING: Missing Setup Data","")) -> WARNING: Missing Financial Data | F11: =IF(COUNT(Fin_Inputs_Entity5!B5:F37)=0,"WARNING: Missing Financial Data",IF(OR(FX_Conversion!B8="",Entity_Ownership!F8="",Entity_Ownership!G8=""),"WARNING: Missing Setup Data","")) -> WARNING: Missing Financial Data | G11: =IF(COUNT(Fin_Inputs_Entity6!B5:F37)=0,"WARNING: Missing Financial Data",IF(OR(FX_Conversion!B9="",Entity_Ownership!F9="",Entity_Ownership!G9=""),"WARNING: Missing Setup Data","")) -> WARNING: Missing Financial Data | H11: =IF(COUNT(Fin_Inputs_Entity7!B5:F37)=0,"WARNING: Missing Financial Data",IF(OR(FX_Conversion!B10="",Entity_Ownership!F10="",Entity_Ownership!G10=""),"WARNING: Missing Setup Data","")) -> WARNING: Missing Financial Data | I11: =IF(COUNT(Fin_Inputs_Entity8!B5:F37)=0,"WARNING: Missing Financial Data",IF(OR(FX_Conversion!B11="",Entity_Ownership!F11="",Entity_Ownership!G11=""),"WARNING: Missing Setup Data","")) -> WARNING: Missing Financial Data | J11: =IF(COUNT(Fin_Inputs_Entity9!B5:F37)=0,"WARNING: Missing Financial Data",IF(OR(FX_Conversion!B12="",Entity_Ownership!F12="",Entity_Ownership!G12=""),"WARNING: Missing Setup Data","")) -> WARNING: Missing Financial Data | K11: =IF(COUNT(Fin_Inputs_Entity10!B5:F37)=0,"WARNING: Missing Financial Data",IF(OR(FX_Conversion!B13="",Entity_Ownership!F13="",Entity_Ownership!G13=""),"WARNING: Missing Setup Data","")) -> WARNING: Missing Financial Data | L11: =IF(COUNTIF(B11:K11,"WARNING*")>0,"WARNING: Missing Data in One or More Entities","") -> WARNING: Missing Data in One or More Entities
A13: FCF Contribution Analysis
A14: Metric / Year | B14: Entity 1 | C14: Entity 2 | D14: Entity 3 | E14: Entity 4 | F14: Entity 5 | G14: Entity 6 | H14: Entity 7 | I14: Entity 8 | J14: Entity 9 | K14: Entity 10 | L14: Combined
A15: FCF Year 1 | B15: =IF(Valuation_Entity1!B18="","",Valuation_Entity1!B18*IF(Entity_Ownership!C4="",1,Entity_Ownership!C4)) | C15: =IF(Valuation_Entity2!B18="","",Valuation_Entity2!B18*IF(Entity_Ownership!C5="",1,Entity_Ownership!C5)) | D15: =IF(Valuation_Entity3!B18="","",Valuation_Entity3!B18*IF(Entity_Ownership!C6="",1,Entity_Ownership!C6)) | E15: =IF(Valuation_Entity4!B18="","",Valuation_Entity4!B18*IF(Entity_Ownership!C7="",1,Entity_Ownership!C7)) | F15: =IF(Valuation_Entity5!B18="","",Valuation_Entity5!B18*IF(Entity_Ownership!C8="",1,Entity_Ownership!C8)) | G15: =IF(Valuation_Entity6!B18="","",Valuation_Entity6!B18*IF(Entity_Ownership!C9="",1,Entity_Ownership!C9)) | H15: =IF(Valuation_Entity7!B18="","",Valuation_Entity7!B18*IF(Entity_Ownership!C10="",1,Entity_Ownership!C10)) | I15: =IF(Valuation_Entity8!B18="","",Valuation_Entity8!B18*IF(Entity_Ownership!C11="",1,Entity_Ownership!C11)) | J15: =IF(Valuation_Entity9!B18="","",Valuation_Entity9!B18*IF(Entity_Ownership!C12="",1,Entity_Ownership!C12)) | K15: =IF(Valuation_Entity10!B18="","",Valuation_Entity10!B18*IF(Entity_Ownership!C13="",1,Entity_Ownership!C13)) | L15: =SUM(B15:K15) -> 0
A16: FCF Year 2 | B16: =IF(Valuation_Entity1!C18="","",Valuation_Entity1!C18*IF(Entity_Ownership!C4="",1,Entity_Ownership!C4)) | C16: =IF(Valuation_Entity2!C18="","",Valuation_Entity2!C18*IF(Entity_Ownership!C5="",1,Entity_Ownership!C5)) | D16: =IF(Valuation_Entity3!C18="","",Valuation_Entity3!C18*IF(Entity_Ownership!C6="",1,Entity_Ownership!C6)) | E16: =IF(Valuation_Entity4!C18="","",Valuation_Entity4!C18*IF(Entity_Ownership!C7="",1,Entity_Ownership!C7)) | F16: =IF(Valuation_Entity5!C18="","",Valuation_Entity5!C18*IF(Entity_Ownership!C8="",1,Entity_Ownership!C8)) | G16: =IF(Valuation_Entity6!C18="","",Valuation_Entity6!C18*IF(Entity_Ownership!C9="",1,Entity_Ownership!C9)) | H16: =IF(Valuation_Entity7!C18="","",Valuation_Entity7!C18*IF(Entity_Ownership!C10="",1,Entity_Ownership!C10)) | I16: =IF(Valuation_Entity8!C18="","",Valuation_Entity8!C18*IF(Entity_Ownership!C11="",1,Entity_Ownership!C11)) | J16: =IF(Valuation_Entity9!C18="","",Valuation_Entity9!C18*IF(Entity_Ownership!C12="",1,Entity_Ownership!C12)) | K16: =IF(Valuation_Entity10!C18="","",Valuation_Entity10!C18*IF(Entity_Ownership!C13="",1,Entity_Ownership!C13)) | L16: =SUM(B16:K16) -> 0
A17: FCF Year 3 | B17: =IF(Valuation_Entity1!D18="","",Valuation_Entity1!D18*IF(Entity_Ownership!C4="",1,Entity_Ownership!C4)) | C17: =IF(Valuation_Entity2!D18="","",Valuation_Entity2!D18*IF(Entity_Ownership!C5="",1,Entity_Ownership!C5)) | D17: =IF(Valuation_Entity3!D18="","",Valuation_Entity3!D18*IF(Entity_Ownership!C6="",1,Entity_Ownership!C6)) | E17: =IF(Valuation_Entity4!D18="","",Valuation_Entity4!D18*IF(Entity_Ownership!C7="",1,Entity_Ownership!C7)) | F17: =IF(Valuation_Entity5!D18="","",Valuation_Entity5!D18*IF(Entity_Ownership!C8="",1,Entity_Ownership!C8)) | G17: =IF(Valuation_Entity6!D18="","",Valuation_Entity6!D18*IF(Entity_Ownership!C9="",1,Entity_Ownership!C9)) | H17: =IF(Valuation_Entity7!D18="","",Valuation_Entity7!D18*IF(Entity_Ownership!C10="",1,Entity_Ownership!C10)) | I17: =IF(Valuation_Entity8!D18="","",Valuation_Entity8!D18*IF(Entity_Ownership!C11="",1,Entity_Ownership!C11)) | J17: =IF(Valuation_Entity9!D18="","",Valuation_Entity9!D18*IF(Entity_Ownership!C12="",1,Entity_Ownership!C12)) | K17: =IF(Valuation_Entity10!D18="","",Valuation_Entity10!D18*IF(Entity_Ownership!C13="",1,Entity_Ownership!C13)) | L17: =SUM(B17:K17) -> 0
A18: FCF Year 4 | B18: =IF(Valuation_Entity1!E18="","",Valuation_Entity1!E18*IF(Entity_Ownership!C4="",1,Entity_Ownership!C4)) | C18: =IF(Valuation_Entity2!E18="","",Valuation_Entity2!E18*IF(Entity_Ownership!C5="",1,Entity_Ownership!C5)) | D18: =IF(Valuation_Entity3!E18="","",Valuation_Entity3!E18*IF(Entity_Ownership!C6="",1,Entity_Ownership!C6)) | E18: =IF(Valuation_Entity4!E18="","",Valuation_Entity4!E18*IF(Entity_Ownership!C7="",1,Entity_Ownership!C7)) | F18: =IF(Valuation_Entity5!E18="","",Valuation_Entity5!E18*IF(Entity_Ownership!C8="",1,Entity_Ownership!C8)) | G18: =IF(Valuation_Entity6!E18="","",Valuation_Entity6!E18*IF(Entity_Ownership!C9="",1,Entity_Ownership!C9)) | H18: =IF(Valuation_Entity7!E18="","",Valuation_Entity7!E18*IF(Entity_Ownership!C10="",1,Entity_Ownership!C10)) | I18: =IF(Valuation_Entity8!E18="","",Valuation_Entity8!E18*IF(Entity_Ownership!C11="",1,Entity_Ownership!C11)) | J18: =IF(Valuation_Entity9!E18="","",Valuation_Entity9!E18*IF(Entity_Ownership!C12="",1,Entity_Ownership!C12)) | K18: =IF(Valuation_Entity10!E18="","",Valuation_Entity10!E18*IF(Entity_Ownership!C13="",1,Entity_Ownership!C13)) | L18: =SUM(B18:K18) -> 0
A19: FCF Year 5 | B19: =IF(Valuation_Entity1!F18="","",Valuation_Entity1!F18*IF(Entity_Ownership!C4="",1,Entity_Ownership!C4)) | C19: =IF(Valuation_Entity2!F18="","",Valuation_Entity2!F18*IF(Entity_Ownership!C5="",1,Entity_Ownership!C5)) | D19: =IF(Valuation_Entity3!F18="","",Valuation_Entity3!F18*IF(Entity_Ownership!C6="",1,Entity_Ownership!C6)) | E19: =IF(Valuation_Entity4!F18="","",Valuation_Entity4!F18*IF(Entity_Ownership!C7="",1,Entity_Ownership!C7)) | F19: =IF(Valuation_Entity5!F18="","",Valuation_Entity5!F18*IF(Entity_Ownership!C8="",1,Entity_Ownership!C8)) | G19: =IF(Valuation_Entity6!F18="","",Valuation_Entity6!F18*IF(Entity_Ownership!C9="",1,Entity_Ownership!C9)) | H19: =IF(Valuation_Entity7!F18="","",Valuation_Entity7!F18*IF(Entity_Ownership!C10="",1,Entity_Ownership!C10)) | I19: =IF(Valuation_Entity8!F18="","",Valuation_Entity8!F18*IF(Entity_Ownership!C11="",1,Entity_Ownership!C11)) | J19: =IF(Valuation_Entity9!F18="","",Valuation_Entity9!F18*IF(Entity_Ownership!C12="",1,Entity_Ownership!C12)) | K19: =IF(Valuation_Entity10!F18="","",Valuation_Entity10!F18*IF(Entity_Ownership!C13="",1,Entity_Ownership!C13)) | L19: =SUM(B19:K19) -> 0
A20: Valuation Contribution Analysis
A21: Entity | B21: Value | C21: Contribution %
A22: Entity 1 | B22: =Valuation_Entity1!B37 | C22: =IF(OR($L$9="",$L$9=0,B22=""),"",B22/$L$9)
A23: Entity 2 | B23: =Valuation_Entity2!B37 | C23: =IF(OR($L$9="",$L$9=0,B23=""),"",B23/$L$9)
A24: Entity 3 | B24: =Valuation_Entity3!B37 | C24: =IF(OR($L$9="",$L$9=0,B24=""),"",B24/$L$9)
A25: Entity 4 | B25: =Valuation_Entity4!B37 | C25: =IF(OR($L$9="",$L$9=0,B25=""),"",B25/$L$9)
A26: Entity 5 | B26: =Valuation_Entity5!B37 | C26: =IF(OR($L$9="",$L$9=0,B26=""),"",B26/$L$9)
A27: Entity 6 | B27: =Valuation_Entity6!B37 | C27: =IF(OR($L$9="",$L$9=0,B27=""),"",B27/$L$9)
A28: Entity 7 | B28: =Valuation_Entity7!B37 | C28: =IF(OR($L$9="",$L$9=0,B28=""),"",B28/$L$9)
A29: Entity 8 | B29: =Valuation_Entity8!B37 | C29: =IF(OR($L$9="",$L$9=0,B29=""),"",B29/$L$9)
A30: Entity 9 | B30: =Valuation_Entity9!B37 | C30: =IF(OR($L$9="",$L$9=0,B30=""),"",B30/$L$9)
A31: Entity 10 | B31: =Valuation_Entity10!B37 | C31: =IF(OR($L$9="",$L$9=0,B31=""),"",B31/$L$9)
A32: JV Readiness | B32: Ownership % applied after FX conversion; JV split fields remain ready for future AI inputs
A33: Revenue Synergies | B33: =0 -> 0 | C33: =IFERROR(B33/G15,0) -> 0 | L33: =Valuation_Entity3!B37 | M33: =IF(OR($L$9="",$L$9=0,B24=""),"",B24/$L$9)
A34: Cost Synergies | B34: =0 -> 0 | C34: =IFERROR(B34/G15,0) -> 0 | L34: =Valuation_Entity10!B37 | M34: =IF(OR($L$9="",$L$9=0,B31=""),"",B31/$L$9)
A35: Operational Efficiencies | B35: =0 -> 0 | C35: =IFERROR(B35/G15,0) -> 0
A36: Total Synergies | B36: =SUM(B33:B35) -> 0 | C36: =IFERROR(B36/G15,0) -> 0
A37: Pro Forma EBITDA (w/ Synergies) | B37: =IF(L5="","",L5+B36) -> 0

Sheet Review_Checks
A1: MODEL REVIEW CHECKS | X1: List_Country | Y1: United States | Z1: Canada | AA1: United Kingdom | AB1: Germany | AC1: France | AD1: Japan | AE1: Australia | AF1: Mexico | AG1: Other
X2: List_Currency | Y2: USD | Z2: EUR | AA2: GBP | AB2: CAD | AC2: JPY | AD2: AUD | AE2: MXN | AF2: CHF | AG2: Other
A3: Check | B3: Result | C3: Status | D3: Notes
A4: 1. Balance Sheet Balances | B4: =IF(OR(Fin_Inputs_Entity1!F23=0,Fin_Inputs_Entity1!F23=(Fin_Inputs_Entity1!F28+Fin_Inputs_Entity1!F29)),"PASS","FAIL") -> PASS | C4: =IF(B4="PASS","✓",IF(B4="FAIL","✗","?")) -> ✓ | D4: Assets = Liabilities + Equity
A5: 2. Cash Flow Reconciliation | B5: =IF(OR(Fin_Inputs_Entity1!F37=0,Fin_Inputs_Entity1!F37=(Fin_Inputs_Entity1!F33+Fin_Inputs_Entity1!F34-Fin_Inputs_Entity1!F35-Fin_Inputs_Entity1!F36)),"PASS","FAIL") -> PASS | C5: =IF(B5="PASS","✓",IF(B5="FAIL","✗","?")) -> ✓ | D5: FCF ties to change in cash
A6: 3. Missing Data Check | B6: =IF(COUNTBLANK(Fin_Inputs_Entity1!B5:F14)>0,"FAIL","PASS") -> FAIL | C6: =IF(B6="PASS","✓",IF(B6="FAIL","✗","?")) -> ✗ | D6: All required inputs populated
A7: 4. Outlier Detection | B7: =IF(OR(IFERROR(ABS(Fin_Inputs_Entity1!F5/Fin_Inputs_Entity1!B5-1),0)>1,IFERROR(ABS(Fin_Inputs_Entity1!F9/Fin_Inputs_Entity1!B9-1),0)>2),"FAIL","PASS") -> PASS | C7: =IF(B7="PASS","✓",IF(B7="FAIL","✗","?")) -> ✓ | D7: No unusual growth/margin spikes
A8: 5. FX Conversion Applied | B8: =IF(NR_FX_Final>0,"PASS","FAIL") -> PASS | C8: =IF(B8="PASS","✓",IF(B8="FAIL","✗","?")) -> ✓ | D8: USD rate entered
A9: 6. Formula Integrity | B9: =IF(AND(NR_Final_Valuation>=0,NR_DCF_Value>=0),"PASS","FAIL") -> PASS | C9: =IF(B9="PASS","✓",IF(B9="FAIL","✗","?")) -> ✓ | D9: No circular references
A11: SUMMARY
A12: Total Checks | B12: =6 -> 6
A13: Passed | B13: =COUNTIF(B4:B9,"PASS") -> 5
A14: Failed/Review | B14: =COUNTIF(B4:B9,"FAIL")+COUNTIF(B4:B9,"CHECK") -> 1
A15: Overall Status | B15: =IF(B14=0,"ALL PASSED",IF(COUNTIF(B4:B9,"FAIL")>0,"REVIEW REQUIRED","NEEDS ATTENTION")) -> REVIEW REQUIRED

Sheet Export_Report
A1: VALUATION EXPORT REPORT
A3: CLIENT INFORMATION
A4: Client Name | B4: =NR_Client_Name -> 0
A5: Valuation Date | B5: =NR_Valuation_Date -> 0
A6: Service Line | B6: =NR_Service_Line -> 0
A7: Industry | B7: =NR_Industry -> 0
A8: Location | B8: =NR_Location -> 0
A10: FINAL VALUATION
A11: DCF Value | B11: =NR_DCF_Value
A12: Market Multiples Value | B12: =NR_Multiples_Value -> Valuation!D30
A13: Final Valuation | B13: =NR_Final_Valuation
A15: KEY PERFORMANCE INDICATORS
A16: Revenue CAGR | B16: =KPIs!C4
A17: EBITDA Margin | B17: =KPIs!C6
A18: Net Margin | B18: =KPIs!C7
A19: Debt/EBITDA | B19: =KPIs!C11
A20: ROE | B20: =KPIs!C14
A22: BENCHMARK SUMMARY
A23: Metric | B23: Client | C23: Industry
A24: EBITDA Margin | B24: =KPIs!C6 | C24: =Benchmarking!C5 -> 0
A25: Net Margin | B25: =KPIs!C7 | C25: =Benchmarking!C6 -> 0
A26: Revenue Growth | B26: =KPIs!C4 | C26: =Benchmarking!C4 -> 0
A28: NARRATIVE SUMMARY
A29: Executive Summary:
A30: [Enter executive summary here]
A32: Key Findings:
A33: [Enter key findings here]
A35: Risks & Considerations:
A36: [Enter risks here]
A38: Recommendation:
A39: [Enter recommendation here]
A41: CHART REFERENCES
A42: Revenue Growth Chart | B42: See Charts tab
A43: EBITDA Margin Trend | B43: See Charts tab
A44: Valuation Summary | B44: See Charts tab
A45: Benchmark Comparison | B45: See Charts tab

Sheet Fin_Inputs_Entity4
A1: ENTITY 4 FINANCIAL INPUTS
A3: INCOME STATEMENT
A4: Line Item | B4: Year 1 | C4: Year 2 | D4: Year 3 | E4: Year 4 | F4: Year 5
A5: Revenue
A6: COGS
A7: Gross Profit
A8: Operating Expenses
A9: EBITDA
A10: Depreciation
A11: EBIT
A12: Interest
A13: Taxes
A14: Net Income
A16: BALANCE SHEET
A17: Line Item | B17: Year 1 | C17: Year 2 | D17: Year 3 | E17: Year 4 | F17: Year 5
A18: Cash
A19: AR
A20: Inventory
A21: Current Assets
A22: PP&E
A23: Total Assets
A24: AP
A25: Accrued Liabilities
A26: Short-Term Debt
A27: Long-Term Debt
A28: Total Liabilities
A29: Equity
A31: CASH FLOW STATEMENT
A32: Line Item | B32: Year 1 | C32: Year 2 | D32: Year 3 | E32: Year 4 | F32: Year 5
A33: Net Income
A34: Depreciation
A35: Working Capital Changes
A36: Capex
A37: Free Cash Flow

Sheet Fin_Inputs_Entity5
A1: ENTITY 5 FINANCIAL INPUTS
A3: INCOME STATEMENT
A4: Line Item | B4: Year 1 | C4: Year 2 | D4: Year 3 | E4: Year 4 | F4: Year 5
A5: Revenue
A6: COGS
A7: Gross Profit
A8: Operating Expenses
A9: EBITDA
A10: Depreciation
A11: EBIT
A12: Interest
A13: Taxes
A14: Net Income
A16: BALANCE SHEET
A17: Line Item | B17: Year 1 | C17: Year 2 | D17: Year 3 | E17: Year 4 | F17: Year 5
A18: Cash
A19: AR
A20: Inventory
A21: Current Assets
A22: PP&E
A23: Total Assets
A24: AP
A25: Accrued Liabilities
A26: Short-Term Debt
A27: Long-Term Debt
A28: Total Liabilities
A29: Equity
A31: CASH FLOW STATEMENT
A32: Line Item | B32: Year 1 | C32: Year 2 | D32: Year 3 | E32: Year 4 | F32: Year 5
A33: Net Income
A34: Depreciation
A35: Working Capital Changes
A36: Capex
A37: Free Cash Flow

Sheet Fin_Inputs_Entity6
A1: ENTITY 6 FINANCIAL INPUTS
A3: INCOME STATEMENT
A4: Line Item | B4: Year 1 | C4: Year 2 | D4: Year 3 | E4: Year 4 | F4: Year 5
A5: Revenue
A6: COGS
A7: Gross Profit
A8: Operating Expenses
A9: EBITDA
A10: Depreciation
A11: EBIT
A12: Interest
A13: Taxes
A14: Net Income
A16: BALANCE SHEET
A17: Line Item | B17: Year 1 | C17: Year 2 | D17: Year 3 | E17: Year 4 | F17: Year 5
A18: Cash
A19: AR
A20: Inventory
A21: Current Assets
A22: PP&E
A23: Total Assets
A24: AP
A25: Accrued Liabilities
A26: Short-Term Debt
A27: Long-Term Debt
A28: Total Liabilities
A29: Equity
A31: CASH FLOW STATEMENT
A32: Line Item | B32: Year 1 | C32: Year 2 | D32: Year 3 | E32: Year 4 | F32: Year 5
A33: Net Income
A34: Depreciation
A35: Working Capital Changes
A36: Capex
A37: Free Cash Flow

Sheet Fin_Inputs_Entity7
A1: ENTITY 7 FINANCIAL INPUTS
A3: INCOME STATEMENT
A4: Line Item | B4: Year 1 | C4: Year 2 | D4: Year 3 | E4: Year 4 | F4: Year 5
A5: Revenue
A6: COGS
A7: Gross Profit
A8: Operating Expenses
A9: EBITDA
A10: Depreciation
A11: EBIT
A12: Interest
A13: Taxes
A14: Net Income
A16: BALANCE SHEET
A17: Line Item | B17: Year 1 | C17: Year 2 | D17: Year 3 | E17: Year 4 | F17: Year 5
A18: Cash
A19: AR
A20: Inventory
A21: Current Assets
A22: PP&E
A23: Total Assets
A24: AP
A25: Accrued Liabilities
A26: Short-Term Debt
A27: Long-Term Debt
A28: Total Liabilities
A29: Equity
A31: CASH FLOW STATEMENT
A32: Line Item | B32: Year 1 | C32: Year 2 | D32: Year 3 | E32: Year 4 | F32: Year 5
A33: Net Income
A34: Depreciation
A35: Working Capital Changes
A36: Capex
A37: Free Cash Flow

Sheet Fin_Inputs_Entity8
A1: ENTITY 8 FINANCIAL INPUTS
A3: INCOME STATEMENT
A4: Line Item | B4: Year 1 | C4: Year 2 | D4: Year 3 | E4: Year 4 | F4: Year 5
A5: Revenue
A6: COGS
A7: Gross Profit
A8: Operating Expenses
A9: EBITDA
A10: Depreciation
A11: EBIT
A12: Interest
A13: Taxes
A14: Net Income
A16: BALANCE SHEET
A17: Line Item | B17: Year 1 | C17: Year 2 | D17: Year 3 | E17: Year 4 | F17: Year 5
A18: Cash
A19: AR
A20: Inventory
A21: Current Assets
A22: PP&E
A23: Total Assets
A24: AP
A25: Accrued Liabilities
A26: Short-Term Debt
A27: Long-Term Debt
A28: Total Liabilities
A29: Equity
A31: CASH FLOW STATEMENT
A32: Line Item | B32: Year 1 | C32: Year 2 | D32: Year 3 | E32: Year 4 | F32: Year 5
A33: Net Income
A34: Depreciation
A35: Working Capital Changes
A36: Capex
A37: Free Cash Flow

Sheet Fin_Inputs_Entity9
A1: ENTITY 9 FINANCIAL INPUTS
A3: INCOME STATEMENT
A4: Line Item | B4: Year 1 | C4: Year 2 | D4: Year 3 | E4: Year 4 | F4: Year 5
A5: Revenue
A6: COGS
A7: Gross Profit
A8: Operating Expenses
A9: EBITDA
A10: Depreciation
A11: EBIT
A12: Interest
A13: Taxes
A14: Net Income
A16: BALANCE SHEET
A17: Line Item | B17: Year 1 | C17: Year 2 | D17: Year 3 | E17: Year 4 | F17: Year 5
A18: Cash
A19: AR
A20: Inventory
A21: Current Assets
A22: PP&E
A23: Total Assets
A24: AP
A25: Accrued Liabilities
A26: Short-Term Debt
A27: Long-Term Debt
A28: Total Liabilities
A29: Equity
A31: CASH FLOW STATEMENT
A32: Line Item | B32: Year 1 | C32: Year 2 | D32: Year 3 | E32: Year 4 | F32: Year 5
A33: Net Income
A34: Depreciation
A35: Working Capital Changes
A36: Capex
A37: Free Cash Flow

Sheet Fin_Inputs_Entity10
A1: ENTITY 10 FINANCIAL INPUTS
A3: INCOME STATEMENT
A4: Line Item | B4: Year 1 | C4: Year 2 | D4: Year 3 | E4: Year 4 | F4: Year 5
A5: Revenue
A6: COGS
A7: Gross Profit
A8: Operating Expenses
A9: EBITDA
A10: Depreciation
A11: EBIT
A12: Interest
A13: Taxes
A14: Net Income
A16: BALANCE SHEET
A17: Line Item | B17: Year 1 | C17: Year 2 | D17: Year 3 | E17: Year 4 | F17: Year 5
A18: Cash
A19: AR
A20: Inventory
A21: Current Assets
A22: PP&E
A23: Total Assets
A24: AP
A25: Accrued Liabilities
A26: Short-Term Debt
A27: Long-Term Debt
A28: Total Liabilities
A29: Equity
A31: CASH FLOW STATEMENT
A32: Line Item | B32: Year 1 | C32: Year 2 | D32: Year 3 | E32: Year 4 | F32: Year 5
A33: Net Income
A34: Depreciation
A35: Working Capital Changes
A36: Capex
A37: Free Cash Flow

Sheet Global_Rates
A1: GLOBAL RATES - PREVIOUS MONTH-END
A3: Rate Name | B3: Entity | C3: Country | D3: Currency | E3: Previous Month-End Date | F3: Value Used | G3: Source URL | H3: AI_Fetched (Yes/No) | I3: Manual Override (Yes/No) | J3: Purpose | K3: Warning
A4: U.S. 10-Year Treasury | B4: Entity 1 | C4: United States | D4: USD | E4: =EOMONTH(TODAY(),-1) -> 46142 | H4: =IF(OR(F4="",G4=""),"","Yes") | J4: WACC / CAPM | K4: =IF(OR(A4="Local 10-Year Government Bond Yield",A4="Local Market Risk Premium",A4="Local Corporate Bond Yield"),IF(OR(C4="",D4=""),"WARNING: Missing Country/Currency Data",IF(F4="","WARNING: Rate Missing — Fallback Value Used","")),IF(F4="","WARNING: Rate Missing — Fallback Value Used","")) -> WARNING: Rate Missing — Fallback Value Used
A5: U.S. Market Risk Premium | B5: Entity 1 | C5: United States | D5: USD | E5: =EOMONTH(TODAY(),-1) -> 46142 | H5: =IF(OR(F5="",G5=""),"","Yes") | J5: CAPM | K5: =IF(OR(A5="Local 10-Year Government Bond Yield",A5="Local Market Risk Premium",A5="Local Corporate Bond Yield"),IF(OR(C5="",D5=""),"WARNING: Missing Country/Currency Data",IF(F5="","WARNING: Rate Missing — Fallback Value Used","")),IF(F5="","WARNING: Rate Missing — Fallback Value Used","")) -> WARNING: Rate Missing — Fallback Value Used
A6: U.S. Corporate Bond Yield | B6: Entity 1 | C6: United States | D6: USD | E6: =EOMONTH(TODAY(),-1) -> 46142 | H6: =IF(OR(F6="",G6=""),"","Yes") | J6: WACC / Loan Readiness | K6: =IF(OR(A6="Local 10-Year Government Bond Yield",A6="Local Market Risk Premium",A6="Local Corporate Bond Yield"),IF(OR(C6="",D6=""),"WARNING: Missing Country/Currency Data",IF(F6="","WARNING: Rate Missing — Fallback Value Used","")),IF(F6="","WARNING: Rate Missing — Fallback Value Used","")) -> WARNING: Rate Missing — Fallback Value Used
A7: Beta | B7: Entity 1 | C7: United States | D7: USD | E7: =EOMONTH(TODAY(),-1) -> 46142 | H7: =IF(OR(F7="",G7=""),"","Yes") | J7: CAPM | K7: =IF(OR(A7="Local 10-Year Government Bond Yield",A7="Local Market Risk Premium",A7="Local Corporate Bond Yield"),IF(OR(C7="",D7=""),"WARNING: Missing Country/Currency Data",IF(F7="","WARNING: Rate Missing — Fallback Value Used","")),IF(F7="","WARNING: Rate Missing — Fallback Value Used","")) -> WARNING: Rate Missing — Fallback Value Used
A8: Local 10-Year Government Bond Yield | B8: Entity 1 | C8: =IF(Entity_Ownership!F4="","",Entity_Ownership!F4) | D8: =IF(Entity_Ownership!G4="","",Entity_Ownership!G4) | E8: =EOMONTH(TODAY(),-1) -> 46142 | H8: =IF(OR(F8="",G8=""),"","Yes") | J8: WACC / CAPM | K8: =IF(OR(A8="Local 10-Year Government Bond Yield",A8="Local Market Risk Premium",A8="Local Corporate Bond Yield"),IF(OR(C8="",D8=""),"WARNING: Missing Country/Currency Data",IF(F8="","WARNING: Rate Missing — Fallback Value Used","")),IF(F8="","WARNING: Rate Missing — Fallback Value Used","")) -> WARNING: Missing Country/Currency Data
A9: Local Market Risk Premium | B9: Entity 1 | C9: =IF(Entity_Ownership!F4="","",Entity_Ownership!F4) | D9: =IF(Entity_Ownership!G4="","",Entity_Ownership!G4) | E9: =EOMONTH(TODAY(),-1) -> 46142 | H9: =IF(OR(F9="",G9=""),"","Yes") | J9: CAPM | K9: =IF(OR(A9="Local 10-Year Government Bond Yield",A9="Local Market Risk Premium",A9="Local Corporate Bond Yield"),IF(OR(C9="",D9=""),"WARNING: Missing Country/Currency Data",IF(F9="","WARNING: Rate Missing — Fallback Value Used","")),IF(F9="","WARNING: Rate Missing — Fallback Value Used","")) -> WARNING: Missing Country/Currency Data
A10: Local Corporate Bond Yield | B10: Entity 1 | C10: =IF(Entity_Ownership!F4="","",Entity_Ownership!F4) | D10: =IF(Entity_Ownership!G4="","",Entity_Ownership!G4) | E10: =EOMONTH(TODAY(),-1) -> 46142 | H10: =IF(OR(F10="",G10=""),"","Yes") | J10: WACC / Loan Readiness | K10: =IF(OR(A10="Local 10-Year Government Bond Yield",A10="Local Market Risk Premium",A10="Local Corporate Bond Yield"),IF(OR(C10="",D10=""),"WARNING: Missing Country/Currency Data",IF(F10="","WARNING: Rate Missing — Fallback Value Used","")),IF(F10="","WARNING: Rate Missing — Fallback Value Used","")) -> WARNING: Missing Country/Currency Data
A11: U.S. 10-Year Treasury | B11: Entity 2 | C11: United States | D11: USD | E11: =EOMONTH(TODAY(),-1) -> 46142 | H11: =IF(OR(F11="",G11=""),"","Yes") | J11: WACC / CAPM | K11: =IF(OR(A11="Local 10-Year Government Bond Yield",A11="Local Market Risk Premium",A11="Local Corporate Bond Yield"),IF(OR(C11="",D11=""),"WARNING: Missing Country/Currency Data",IF(F11="","WARNING: Rate Missing — Fallback Value Used","")),IF(F11="","WARNING: Rate Missing — Fallback Value Used","")) -> WARNING: Rate Missing — Fallback Value Used
A12: U.S. Market Risk Premium | B12: Entity 2 | C12: United States | D12: USD | E12: =EOMONTH(TODAY(),-1) -> 46142 | H12: =IF(OR(F12="",G12=""),"","Yes") | J12: CAPM | K12: =IF(OR(A12="Local 10-Year Government Bond Yield",A12="Local Market Risk Premium",A12="Local Corporate Bond Yield"),IF(OR(C12="",D12=""),"WARNING: Missing Country/Currency Data",IF(F12="","WARNING: Rate Missing — Fallback Value Used","")),IF(F12="","WARNING: Rate Missing — Fallback Value Used","")) -> WARNING: Rate Missing — Fallback Value Used
A13: U.S. Corporate Bond Yield | B13: Entity 2 | C13: United States | D13: USD | E13: =EOMONTH(TODAY(),-1) -> 46142 | H13: =IF(OR(F13="",G13=""),"","Yes") | J13: WACC / Loan Readiness | K13: =IF(OR(A13="Local 10-Year Government Bond Yield",A13="Local Market Risk Premium",A13="Local Corporate Bond Yield"),IF(OR(C13="",D13=""),"WARNING: Missing Country/Currency Data",IF(F13="","WARNING: Rate Missing — Fallback Value Used","")),IF(F13="","WARNING: Rate Missing — Fallback Value Used","")) -> WARNING: Rate Missing — Fallback Value Used
A14: Beta | B14: Entity 2 | C14: United States | D14: USD | E14: =EOMONTH(TODAY(),-1) -> 46142 | H14: =IF(OR(F14="",G14=""),"","Yes") | J14: CAPM | K14: =IF(OR(A14="Local 10-Year Government Bond Yield",A14="Local Market Risk Premium",A14="Local Corporate Bond Yield"),IF(OR(C14="",D14=""),"WARNING: Missing Country/Currency Data",IF(F14="","WARNING: Rate Missing — Fallback Value Used","")),IF(F14="","WARNING: Rate Missing — Fallback Value Used","")) -> WARNING: Rate Missing — Fallback Value Used
A15: Local 10-Year Government Bond Yield | B15: Entity 2 | C15: =IF(Entity_Ownership!F5="","",Entity_Ownership!F5) | D15: =IF(Entity_Ownership!G5="","",Entity_Ownership!G5) | E15: =EOMONTH(TODAY(),-1) -> 46142 | H15: =IF(OR(F15="",G15=""),"","Yes") | J15: WACC / CAPM | K15: =IF(OR(A15="Local 10-Year Government Bond Yield",A15="Local Market Risk Premium",A15="Local Corporate Bond Yield"),IF(OR(C15="",D15=""),"WARNING: Missing Country/Currency Data",IF(F15="","WARNING: Rate Missing — Fallback Value Used","")),IF(F15="","WARNING: Rate Missing — Fallback Value Used","")) -> WARNING: Missing Country/Currency Data
A16: Local Market Risk Premium | B16: Entity 2 | C16: =IF(Entity_Ownership!F5="","",Entity_Ownership!F5) | D16: =IF(Entity_Ownership!G5="","",Entity_Ownership!G5) | E16: =EOMONTH(TODAY(),-1) -> 46142 | H16: =IF(OR(F16="",G16=""),"","Yes") | J16: CAPM | K16: =IF(OR(A16="Local 10-Year Government Bond Yield",A16="Local Market Risk Premium",A16="Local Corporate Bond Yield"),IF(OR(C16="",D16=""),"WARNING: Missing Country/Currency Data",IF(F16="","WARNING: Rate Missing — Fallback Value Used","")),IF(F16="","WARNING: Rate Missing — Fallback Value Used","")) -> WARNING: Missing Country/Currency Data
A17: Local Corporate Bond Yield | B17: Entity 2 | C17: =IF(Entity_Ownership!F5="","",Entity_Ownership!F5) | D17: =IF(Entity_Ownership!G5="","",Entity_Ownership!G5) | E17: =EOMONTH(TODAY(),-1) -> 46142 | H17: =IF(OR(F17="",G17=""),"","Yes") | J17: WACC / Loan Readiness | K17: =IF(OR(A17="Local 10-Year Government Bond Yield",A17="Local Market Risk Premium",A17="Local Corporate Bond Yield"),IF(OR(C17="",D17=""),"WARNING: Missing Country/Currency Data",IF(F17="","WARNING: Rate Missing — Fallback Value Used","")),IF(F17="","WARNING: Rate Missing — Fallback Value Used","")) -> WARNING: Missing Country/Currency Data
A18: U.S. 10-Year Treasury | B18: Entity 3 | C18: United States | D18: USD | E18: =EOMONTH(TODAY(),-1) -> 46142 | H18: =IF(OR(F18="",G18=""),"","Yes") | J18: WACC / CAPM | K18: =IF(OR(A18="Local 10-Year Government Bond Yield",A18="Local Market Risk Premium",A18="Local Corporate Bond Yield"),IF(OR(C18="",D18=""),"WARNING: Missing Country/Currency Data",IF(F18="","WARNING: Rate Missing — Fallback Value Used","")),IF(F18="","WARNING: Rate Missing — Fallback Value Used","")) -> WARNING: Rate Missing — Fallback Value Used
