Workbook
Name BaseCase_Local: Scenarios!$B$2
Name BestCase_Local: Scenarios!$B$3
Name BreakEven_Local: Pricing_Logic!$B$5
Name BreakEven_USD: Pricing_Logic!$B$11
Name Business_Name: Client_Info!$B$2
Name Client_City: Client_Info!$B$6
Name Client_Country: Client_Info!$B$4
Name Client_Currency: Client_Info!$B$8
Name Client_Name: Client_Info!$B$1
Name Client_State: Client_Info!$B$5
Name Client_ZIP: Client_Info!$B$7
Name COGS: Product_Input!$F$2
Name COL_Index: Market_Input!$G$2
Name Commodity_Change: Market_Input!$H$2
Name Comp_Avg: Market_Input!$B$2
Name Comp_Max: Market_Input!$D$2
Name Comp_Min: Market_Input!$C$2
Name CompPrice_Local: Pricing_Logic!$B$3
Name CompPrice_USD: Pricing_Logic!$B$9
Name CostPlus_Local: Pricing_Logic!$B$1
Name CostPlus_USD: Pricing_Logic!$B$8
Name Fixed_Cost: Product_Input!$J$2
Name FX_Code: FX_Rates!$A$2:$A$13
Name FX_Rate: FX_Rates!$E$3
Name FX_Value: FX_Rates!$B$2:$B$13
Name Industry: Client_Info!$B$3
Name Inflation_Rate: Market_Input!$E$2
Name InflationPrice_Local: Pricing_Logic!$B$4
Name InflationPrice_USD: Pricing_Logic!$B$10
Name Labor_Cost: Product_Input!$G$2
Name Overhead_Cost: Product_Input!$H$2
Name Position_Adjust: Pricing_Logic!$B$2
Name Positioning: Product_Input!$L$2
Name Prev_Month_End: FX_Rates!$E$2
Name Product_Category: Product_Input!$D$2
Name Product_Description: Product_Input!$C$2
Name Product_Name: Product_Input!$B$2
Name Recommended_Local: Outputs!$B$3
Name Seasonality: Market_Input!$J$2
Name Target_Margin: Product_Input!$K$2
Name Total_Cost: Product_Input!$M$2
Name Unit_Size: Product_Input!$E$2
Name Units_History: Market_Input!$I$2
Name Valuation_Date: FX_Rates!$E$1
Name Variable_Cost: Product_Input!$I$2
Name Wage_Growth: Market_Input!$F$2
Name WorstCase_Local: Scenarios!$B$4

Sheet Dashboard
A1: PRICING MODEL DASHBOARD
A2: Multi-Product Pricing Analysis (25 Products)
A4: KEY PERFORMANCE INDICATORS
A5: Average Margin % | B5: Highest Margin Product | C5: Lowest Margin Product | E5: Model Status
A6: =IFERROR(AVERAGE(Outputs!H2:H26),"N/A") -> 0 | B6: =IFERROR(INDEX(Outputs!B2:B26,MATCH(MAX(Outputs!H2:H26),Outputs!H2:H26,0)),"N/A") -> 0 | C6: {=IFERROR(INDEX(Outputs!B2:B26,MATCH(MIN(IF(Outputs!H2:H26>0,Outputs!H2:H26)),Outputs!H2:H26,0)),"N/A")} -> 0 | E6: =Data_Audit!A1 -> ❌ MODEL BLOCKED — FIX CRITICAL ERRORS
A8: Products Above Comp Avg | B8: Products Below Break-Even | C8: Audit Issues
A9: {=SUMPRODUCT((Outputs!C2:C26>Market_Input!B2:B26)*(Outputs!C2:C26>0)*(Market_Input!B2:B26>0))} -> 0 | B9: {=SUMPRODUCT((Outputs!C2:C26<Outputs!E2:E26)*(Outputs!C2:C26>0))} -> 0 | C9: =Data_Audit!B23 -> 5
A11: DATA STATUS
A12: Field | B12: Status
A13: Client Info | B13: =IF(Client_Info!B1="","❌ Missing","✅ Filled") -> ❌ Missing
A14: Product Data | B14: =IF(COUNTBLANK(Product_Input!B2:B26)=25,"❌ No products","✅ "&(25-COUNTBLANK(Product_Input!B2:B26))&" products") -> ❌ No products
A15: Market Data | B15: =IF(COUNTBLANK(Market_Input!B2:B26)=25,"❌ No data","✅ "&(25-COUNTBLANK(Market_Input!B2:B26))&" rows") -> ❌ No data
A16: FX Rate | B16: =IF(COUNTA(FX_Rates!C2:C13)=0,"❌ No FX","✅ "&COUNTA(FX_Rates!C2:C13)&" rates") -> ❌ No FX
A17: Valuation Date | B17: =IF(FX_Rates!H1="","❌ Not set",TEXT(FX_Rates!H1,"yyyy-mm-dd")) -> ❌ Not set
A18: Prev Month End | B18: =IF(FX_Rates!H1="","❌ N/A",TEXT(EOMONTH(FX_Rates!H1,-1),"yyyy-mm-dd")) -> ❌ N/A
A20: CHART DATA (Auto-populated from formulas)
A21: Price Comparison (First 10 Products) | G21: Margin % (First 10 Products)
A22: Product | B22: Recommended | C22: Cost-Plus | D22: Comp-Based | E22: Break-Even | G22: Product | H22: Margin %
A23: =IF(Product_Input!B2="","Product 1",Product_Input!B2) -> Product 1 | B23: =Outputs!C2 -> 0 | C23: =Pricing_Logic!C2 -> 0 | D23: =Pricing_Logic!E2 -> 0 | E23: =Pricing_Logic!G2 -> 0 | G23: =IF(Product_Input!B2="","Product 1",Product_Input!B2) -> Product 1 | H23: =Outputs!H2 -> 0
A24: =IF(Product_Input!B3="","Product 2",Product_Input!B3) -> Product 2 | B24: =Outputs!C3 -> 0 | C24: =Pricing_Logic!C3 -> 0 | D24: =Pricing_Logic!E3 -> 0 | E24: =Pricing_Logic!G3 -> 0 | G24: =IF(Product_Input!B3="","Product 2",Product_Input!B3) -> Product 2 | H24: =Outputs!H3 -> 0
A25: =IF(Product_Input!B4="","Product 3",Product_Input!B4) -> Product 3 | B25: =Outputs!C4 -> 0 | C25: =Pricing_Logic!C4 -> 0 | D25: =Pricing_Logic!E4 -> 0 | E25: =Pricing_Logic!G4 -> 0 | G25: =IF(Product_Input!B4="","Product 3",Product_Input!B4) -> Product 3 | H25: =Outputs!H4 -> 0
A26: =IF(Product_Input!B5="","Product 4",Product_Input!B5) -> Product 4 | B26: =Outputs!C5 -> 0 | C26: =Pricing_Logic!C5 -> 0 | D26: =Pricing_Logic!E5 -> 0 | E26: =Pricing_Logic!G5 -> 0 | G26: =IF(Product_Input!B5="","Product 4",Product_Input!B5) -> Product 4 | H26: =Outputs!H5 -> 0
A27: =IF(Product_Input!B6="","Product 5",Product_Input!B6) -> Product 5 | B27: =Outputs!C6 -> 0 | C27: =Pricing_Logic!C6 -> 0 | D27: =Pricing_Logic!E6 -> 0 | E27: =Pricing_Logic!G6 -> 0 | G27: =IF(Product_Input!B6="","Product 5",Product_Input!B6) -> Product 5 | H27: =Outputs!H6 -> 0
A28: =IF(Product_Input!B7="","Product 6",Product_Input!B7) -> Product 6 | B28: =Outputs!C7 -> 0 | C28: =Pricing_Logic!C7 -> 0 | D28: =Pricing_Logic!E7 -> 0 | E28: =Pricing_Logic!G7 -> 0 | G28: =IF(Product_Input!B7="","Product 6",Product_Input!B7) -> Product 6 | H28: =Outputs!H7 -> 0
A29: =IF(Product_Input!B8="","Product 7",Product_Input!B8) -> Product 7 | B29: =Outputs!C8 -> 0 | C29: =Pricing_Logic!C8 -> 0 | D29: =Pricing_Logic!E8 -> 0 | E29: =Pricing_Logic!G8 -> 0 | G29: =IF(Product_Input!B8="","Product 7",Product_Input!B8) -> Product 7 | H29: =Outputs!H8 -> 0
A30: =IF(Product_Input!B9="","Product 8",Product_Input!B9) -> Product 8 | B30: =Outputs!C9 -> 0 | C30: =Pricing_Logic!C9 -> 0 | D30: =Pricing_Logic!E9 -> 0 | E30: =Pricing_Logic!G9 -> 0 | G30: =IF(Product_Input!B9="","Product 8",Product_Input!B9) -> Product 8 | H30: =Outputs!H9 -> 0
A31: =IF(Product_Input!B10="","Product 9",Product_Input!B10) -> Product 9 | B31: =Outputs!C10 -> 0 | C31: =Pricing_Logic!C10 -> 0 | D31: =Pricing_Logic!E10 -> 0 | E31: =Pricing_Logic!G10 -> 0 | G31: =IF(Product_Input!B10="","Product 9",Product_Input!B10) -> Product 9 | H31: =Outputs!H10 -> 0
A32: =IF(Product_Input!B11="","Product 10",Product_Input!B11) -> Product 10 | B32: =Outputs!C11 -> 0 | C32: =Pricing_Logic!C11 -> 0 | D32: =Pricing_Logic!E11 -> 0 | E32: =Pricing_Logic!G11 -> 0 | G32: =IF(Product_Input!B11="","Product 10",Product_Input!B11) -> Product 10 | H32: =Outputs!H11 -> 0
A35: Scenario Analysis (First 10 Products)
A36: Product | B36: Worst Case | C36: Base Case | D36: Best Case
A37: =IF(Product_Input!B2="","Product 1",Product_Input!B2) -> Product 1 | B37: =Scenarios!D2 -> 0 | C37: =Scenarios!B2 -> 0 | D37: =Scenarios!C2 -> 0
A38: =IF(Product_Input!B3="","Product 2",Product_Input!B3) -> Product 2 | B38: =Scenarios!D3 -> 0 | C38: =Scenarios!B3 -> 0 | D38: =Scenarios!C3 -> 0
A39: =IF(Product_Input!B4="","Product 3",Product_Input!B4) -> Product 3 | B39: =Scenarios!D4 -> 0 | C39: =Scenarios!B4 -> 0 | D39: =Scenarios!C4 -> 0
A40: =IF(Product_Input!B5="","Product 4",Product_Input!B5) -> Product 4 | B40: =Scenarios!D5 -> 0 | C40: =Scenarios!B5 -> 0 | D40: =Scenarios!C5 -> 0
A41: =IF(Product_Input!B6="","Product 5",Product_Input!B6) -> Product 5 | B41: =Scenarios!D6 -> 0 | C41: =Scenarios!B6 -> 0 | D41: =Scenarios!C6 -> 0
A42: =IF(Product_Input!B7="","Product 6",Product_Input!B7) -> Product 6 | B42: =Scenarios!D7 -> 0 | C42: =Scenarios!B7 -> 0 | D42: =Scenarios!C7 -> 0
A43: =IF(Product_Input!B8="","Product 7",Product_Input!B8) -> Product 7 | B43: =Scenarios!D8 -> 0 | C43: =Scenarios!B8 -> 0 | D43: =Scenarios!C8 -> 0
A44: =IF(Product_Input!B9="","Product 8",Product_Input!B9) -> Product 8 | B44: =Scenarios!D9 -> 0 | C44: =Scenarios!B9 -> 0 | D44: =Scenarios!C9 -> 0
A45: =IF(Product_Input!B10="","Product 9",Product_Input!B10) -> Product 9 | B45: =Scenarios!D10 -> 0 | C45: =Scenarios!B10 -> 0 | D45: =Scenarios!C10 -> 0
A46: =IF(Product_Input!B11="","Product 10",Product_Input!B11) -> Product 10 | B46: =Scenarios!D11 -> 0 | C46: =Scenarios!B11 -> 0 | D46: =Scenarios!C11 -> 0
...

Sheet Client_Info
A1: Client Name
A2: Business Name
A3: Industry
A4: Country
A5: State/Region
A6: City
A7: ZIP/Postal Code
A8: Currency Code
A10: ⚠️ External Data Fields - Must be filled by external AI engine

Sheet Product_Input
A1: Product # | B1: Product Name | C1: Product Description | D1: Category | E1: Unit Size | F1: COGS | G1: Labor Cost | H1: Overhead | I1: Variable Cost | J1: Fixed Cost | K1: Target Margin | L1: Positioning | M1: Total Cost
A2: 1 | M2: =IF(F2="",0,F2+G2+H2+I2+J2) -> 0
A3: 2 | M3: =IF(F3="",0,F3+G3+H3+I3+J3) -> 0
A4: 3 | M4: =IF(F4="",0,F4+G4+H4+I4+J4) -> 0
A5: 4 | M5: =IF(F5="",0,F5+G5+H5+I5+J5) -> 0
A6: 5 | M6: =IF(F6="",0,F6+G6+H6+I6+J6) -> 0
A7: 6 | M7: =IF(F7="",0,F7+G7+H7+I7+J7) -> 0
A8: 7 | M8: =IF(F8="",0,F8+G8+H8+I8+J8) -> 0
A9: 8 | M9: =IF(F9="",0,F9+G9+H9+I9+J9) -> 0
A10: 9 | M10: =IF(F10="",0,F10+G10+H10+I10+J10) -> 0
A11: 10 | M11: =IF(F11="",0,F11+G11+H11+I11+J11) -> 0
A12: 11 | M12: =IF(F12="",0,F12+G12+H12+I12+J12) -> 0
A13: 12 | M13: =IF(F13="",0,F13+G13+H13+I13+J13) -> 0
... A26: 25 | M26: =IF(F26="",0,F26+G26+H26+I26+J26) -> 0

Sheet Market_Input
A1: Product # | B1: Comp Avg Price | C1: Comp Min | D1: Comp Max | E1: Inflation Rate | F1: Wage Growth | G1: COL Index | H1: Commodity Change | I1: Units History | J1: Seasonality
A2: 1
A3: 2
A4: 3
A5: 4
A6: 5
A7: 6
A8: 7
A9: 8
A10: 9
A11: 10
A12: 11
A13: 12
... A26: 25

Sheet FX_Rates
A1: Currency_Code | B1: Prev_Month_End_Date | C1: FX_Rate_Prev_Month_End | D1: Source_URL | E1: Timestamp | G1: Valuation_Date
B2: =IF($H$1="","",EOMONTH($H$1,-1))
B3: =IF($H$1="","",EOMONTH($H$1,-1)) | G3: ⚠️ AI-ONLY FIELDS: • Currency_Code (Col A) • FX_Rate (Col C) • Source_URL (Col D) • Timestamp (Col E)
B4: =IF($H$1="","",EOMONTH($H$1,-1))
B5: =IF($H$1="","",EOMONTH($H$1,-1))
B6: =IF($H$1="","",EOMONTH($H$1,-1))
B7: =IF($H$1="","",EOMONTH($H$1,-1))
B8: =IF($H$1="","",EOMONTH($H$1,-1))
B9: =IF($H$1="","",EOMONTH($H$1,-1))
B10: =IF($H$1="","",EOMONTH($H$1,-1))
B11: =IF($H$1="","",EOMONTH($H$1,-1))
B12: =IF($H$1="","",EOMONTH($H$1,-1))
B13: =IF($H$1="","",EOMONTH($H$1,-1))

Sheet Pricing_Logic
A1: Product # | B1: Total Cost | C1: Cost-Plus (Local) | D1: Position Adjust | E1: Comp Price (Local) | F1: Inflation Price (Local) | G1: Break-Even (Local) | H1: FX Rate | I1: Cost-Plus (USD) | J1: Comp Price (USD) | K1: Inflation Price (USD) | L1: Break-Even (USD)
A2: 1 | B2: =Product_Input!M2 -> 0 | C2: =IF(B2=0,0,B2*(1+Product_Input!K2)) -> 0 | D2: {=IFERROR(_xlfn.IFS(Product_Input!L2="Budget",-0.05,Product_Input!L2="Mid",0,Product_Input!L2="Premium",0.1),0)} -> 0 | E2: =IF(Market_Input!B2="",0,Market_Input!B2*(1+D2)) -> 0 | F2: =IF(C2=0,0,C2*(1+Market_Input!E2)) -> 0 | G2: =B2 -> 0 | H2: =IFERROR(_xlfn.XLOOKUP(Client_Info!$B$8,FX_Rates!$A$2:$A$13,FX_Rates!$C$2:$C$13,1),1) -> 0 | I2: =C2*H2 -> 0 | J2: =E2*H2 -> 0 | K2: =F2*H2 -> 0 | L2: =G2*H2 -> 0
A3: 2 | B3: =Product_Input!M3 -> 0 | C3: =IF(B3=0,0,B3*(1+Product_Input!K3)) -> 0 | D3: {=IFERROR(_xlfn.IFS(Product_Input!L3="Budget",-0.05,Product_Input!L3="Mid",0,Product_Input!L3="Premium",0.1),0)} -> 0 | E3: =IF(Market_Input!B3="",0,Market_Input!B3*(1+D3)) -> 0 | F3: =IF(C3=0,0,C3*(1+Market_Input!E3)) -> 0 | G3: =B3 -> 0 | H3: =IFERROR(_xlfn.XLOOKUP(Client_Info!$B$8,FX_Rates!$A$2:$A$13,FX_Rates!$C$2:$C$13,1),1) -> 0 | I3: =C3*H3 -> 0 | J3: =E3*H3 -> 0 | K3: =F3*H3 -> 0 | L3: =G3*H3 -> 0
A4: 3 | B4: =Product_Input!M4 -> 0 | C4: =IF(B4=0,0,B4*(1+Product_Input!K4)) -> 0 | D4: {=IFERROR(_xlfn.IFS(Product_Input!L4="Budget",-0.05,Product_Input!L4="Mid",0,Product_Input!L4="Premium",0.1),0)} -> 0 | E4: =IF(Market_Input!B4="",0,Market_Input!B4*(1+D4)) -> 0 | F4: =IF(C4=0,0,C4*(1+Market_Input!E4)) -> 0 | G4: =B4 -> 0 | H4: =IFERROR(_xlfn.XLOOKUP(Client_Info!$B$8,FX_Rates!$A$2:$A$13,FX_Rates!$C$2:$C$13,1),1) -> 0 | I4: =C4*H4 -> 0 | J4: =E4*H4 -> 0 | K4: =F4*H4 -> 0 | L4: =G4*H4 -> 0
A5: 4 | B5: =Product_Input!M5 -> 0 | C5: =IF(B5=0,0,B5*(1+Product_Input!K5)) -> 0 | D5: {=IFERROR(_xlfn.IFS(Product_Input!L5="Budget",-0.05,Product_Input!L5="Mid",0,Product_Input!L5="Premium",0.1),0)} -> 0 | E5: =IF(Market_Input!B5="",0,Market_Input!B5*(1+D5)) -> 0 | F5: =IF(C5=0,0,C5*(1+Market_Input!E5)) -> 0 | G5: =B5 -> 0 | H5: =IFERROR(_xlfn.XLOOKUP(Client_Info!$B$8,FX_Rates!$A$2:$A$13,FX_Rates!$C$2:$C$13,1),1) -> 0 | I5: =C5*H5 -> 0 | J5: =E5*H5 -> 0 | K5: =F5*H5 -> 0 | L5: =G5*H5 -> 0
A6: 5 | B6: =Product_Input!M6 -> 0 | C6: =IF(B6=0,0,B6*(1+Product_Input!K6)) -> 0 | D6: {=IFERROR(_xlfn.IFS(Product_Input!L6="Budget",-0.05,Product_Input!L6="Mid",0,Product_Input!L6="Premium",0.1),0)} -> 0 | E6: =IF(Market_Input!B6="",0,Market_Input!B6*(1+D6)) -> 0 | F6: =IF(C6=0,0,C6*(1+Market_Input!E6)) -> 0 | G6: =B6 -> 0 | H6: =IFERROR(_xlfn.XLOOKUP(Client_Info!$B$8,FX_Rates!$A$2:$A$13,FX_Rates!$C$2:$C$13,1),1) -> 0 | I6: =C6*H6 -> 0 | J6: =E6*H6 -> 0 | K6: =F6*H6 -> 0 | L6: =G6*H6 -> 0
A7: 6 | B7: =Product_Input!M7 -> 0 | C7: =IF(B7=0,0,B7*(1+Product_Input!K7)) -> 0 | D7: {=IFERROR(_xlfn.IFS(Product_Input!L7="Budget",-0.05,Product_Input!L7="Mid",0,Product_Input!L7="Premium",0.1),0)} -> 0 | E7: =IF(Market_Input!B7="",0,Market_Input!B7*(1+D7)) -> 0 | F7: =IF(C7=0,0,C7*(1+Market_Input!E7)) -> 0 | G7: =B7 -> 0 | H7: =IFERROR(_xlfn.XLOOKUP(Client_Info!$B$8,FX_Rates!$A$2:$A$13,FX_Rates!$C$2:$C$13,1),1) -> 0 | I7: =C7*H7 -> 0 | J7: =E7*H7 -> 0 | K7: =F7*H7 -> 0 | L7: =G7*H7 -> 0
A8: 7 | B8: =Product_Input!M8 -> 0 | C8: =IF(B8=0,0,B8*(1+Product_Input!K8)) -> 0 | D8: {=IFERROR(_xlfn.IFS(Product_Input!L8="Budget",-0.05,Product_Input!L8="Mid",0,Product_Input!L8="Premium",0.1),0)} -> 0 | E8: =IF(Market_Input!B8="",0,Market_Input!B8*(1+D8)) -> 0 | F8: =IF(C8=0,0,C8*(1+Market_Input!E8)) -> 0 | G8: =B8 -> 0 | H8: =IFERROR(_xlfn.XLOOKUP(Client_Info!$B$8,FX_Rates!$A$2:$A$13,FX_Rates!$C$2:$C$13,1),1) -> 0 | I8: =C8*H8 -> 0 | J8: =E8*H8 -> 0 | K8: =F8*H8 -> 0 | L8: =G8*H8 -> 0
A9: 8 | B9: =Product_Input!M9 -> 0 | C9: =IF(B9=0,0,B9*(1+Product_Input!K9)) -> 0 | D9: {=IFERROR(_xlfn.IFS(Product_Input!L9="Budget",-0.05,Product_Input!L9="Mid",0,Product_Input!L9="Premium",0.1),0)} -> 0 | E9: =IF(Market_Input!B9="",0,Market_Input!B9*(1+D9)) -> 0 | F9: =IF(C9=0,0,C9*(1+Market_Input!E9)) -> 0 | G9: =B9 -> 0 | H9: =IFERROR(_xlfn.XLOOKUP(Client_Info!$B$8,FX_Rates!$A$2:$A$13,FX_Rates!$C$2:$C$13,1),1) -> 0 | I9: =C9*H9 -> 0 | J9: =E9*H9 -> 0 | K9: =F9*H9 -> 0 | L9: =G9*H9 -> 0
A10: 9 | B10: =Product_Input!M10 -> 0 | C10: =IF(B10=0,0,B10*(1+Product_Input!K10)) -> 0 | D10: {=IFERROR(_xlfn.IFS(Product_Input!L10="Budget",-0.05,Product_Input!L10="Mid",0,Product_Input!L10="Premium",0.1),0)} -> 0 | E10: =IF(Market_Input!B10="",0,Market_Input!B10*(1+D10)) -> 0 | F10: =IF(C10=0,0,C10*(1+Market_Input!E10)) -> 0 | G10: =B10 -> 0 | H10: =IFERROR(_xlfn.XLOOKUP(Client_Info!$B$8,FX_Rates!$A$2:$A$13,FX_Rates!$C$2:$C$13,1),1) -> 0 | I10: =C10*H10 -> 0 | J10: =E10*H10 -> 0 | K10: =F10*H10 -> 0 | L10: =G10*H10 -> 0
A11: 10 | B11: =Product_Input!M11 -> 0 | C11: =IF(B11=0,0,B11*(1+Product_Input!K11)) -> 0 | D11: {=IFERROR(_xlfn.IFS(Product_Input!L11="Budget",-0.05,Product_Input!L11="Mid",0,Product_Input!L11="Premium",0.1),0)} -> 0 | E11: =IF(Market_Input!B11="",0,Market_Input!B11*(1+D11)) -> 0 | F11: =IF(C11=0,0,C11*(1+Market_Input!E11)) -> 0 | G11: =B11 -> 0 | H11: =IFERROR(_xlfn.XLOOKUP(Client_Info!$B$8,FX_Rates!$A$2:$A$13,FX_Rates!$C$2:$C$13,1),1) -> 0 | I11: =C11*H11 -> 0 | J11: =E11*H11 -> 0 | K11: =F11*H11 -> 0 | L11: =G11*H11 -> 0
A12: 11 | B12: =Product_Input!M12 -> 0 | C12: =IF(B12=0,0,B12*(1+Product_Input!K12)) -> 0 | D12: {=IFERROR(_xlfn.IFS(Product_Input!L12="Budget",-0.05,Product_Input!L12="Mid",0,Product_Input!L12="Premium",0.1),0)} -> 0 | E12: =IF(Market_Input!B12="",0,Market_Input!B12*(1+D12)) -> 0 | F12: =IF(C12=0,0,C12*(1+Market_Input!E12)) -> 0 | G12: =B12 -> 0 | H12: =IFERROR(_xlfn.XLOOKUP(Client_Info!$B$8,FX_Rates!$A$2:$A$13,FX_Rates!$C$2:$C$13,1),1) -> 0 | I12: =C12*H12 -> 0 | J12: =E12*H12 -> 0 | K12: =F12*H12 -> 0 | L12: =G12*H12 -> 0
A13: 12 | B13: =Product_Input!M13 -> 0 | C13: =IF(B13=0,0,B13*(1+Product_Input!K13)) -> 0 | D13: {=IFERROR(_xlfn.IFS(Product_Input!L13="Budget",-0.05,Product_Input!L13="Mid",0,Product_Input!L13="Premium",0.1),0)} -> 0 | E13: =IF(Market_Input!B13="",0,Market_Input!B13*(1+D13)) -> 0 | F13: =IF(C13=0,0,C13*(1+Market_Input!E13)) -> 0 | G13: =B13 -> 0 | H13: =IFERROR(_xlfn.XLOOKUP(Client_Info!$B$8,FX_Rates!$A$2:$A$13,FX_Rates!$C$2:$C$13,1),1) -> 0 | I13: =C13*H13 -> 0 | J13: =E13*H13 -> 0 | K13: =F13*H13 -> 0 | L13: =G13*H13 -> 0
... A26: 25 | B26: =Product_Input!M26 -> 0 | C26: =IF(B26=0,0,B26*(1+Product_Input!K26)) -> 0 | D26: {=IFERROR(_xlfn.IFS(Product_Input!L26="Budget",-0.05,Product_Input!L26="Mid",0,Product_Input!L26="Premium",0.1),0)} -> 0 | E26: =IF(Market_Input!B26="",0,Market_Input!B26*(1+D26)) -> 0 | F26: =IF(C26=0,0,C26*(1+Market_Input!E26)) -> 0 | G26: =B26 -> 0 | H26: =IFERROR(_xlfn.XLOOKUP(Client_Info!$B$8,FX_Rates!$A$2:$A$13,FX_Rates!$C$2:$C$13,1),1) -> 0 | I26: =C26*H26 -> 0 | J26: =E26*H26 -> 0 | K26: =F26*H26 -> 0 | L26: =G26*H26 -> 0

Sheet Scenarios
A1: Product # | B1: Base Case (Local) | C1: Best Case (Local) | D1: Worst Case (Local) | E1: Units × Season | F1: Base Revenue | G1: Best Revenue | H1: Worst Revenue
A2: 1 | B2: =Pricing_Logic!C2 -> 0 | C2: =B2*1.05 -> 0 | D2: =B2*0.95 -> 0 | E2: =IF(Market_Input!I2="",0,Market_Input!I2*IF(Market_Input!J2="",1,Market_Input!J2)) -> 0 | F2: =B2*E2 -> 0 | G2: =C2*E2 -> 0 | H2: =D2*E2 -> 0
A3: 2 | B3: =Pricing_Logic!C3 -> 0 | C3: =B3*1.05 -> 0 | D3: =B3*0.95 -> 0 | E3: =IF(Market_Input!I3="",0,Market_Input!I3*IF(Market_Input!J3="",1,Market_Input!J3)) -> 0 | F3: =B3*E3 -> 0 | G3: =C3*E3 -> 0 | H3: =D3*E3 -> 0
A4: 3 | B4: =Pricing_Logic!C4 -> 0 | C4: =B4*1.05 -> 0 | D4: =B4*0.95 -> 0 | E4: =IF(Market_Input!I4="",0,Market_Input!I4*IF(Market_Input!J4="",1,Market_Input!J4)) -> 0 | F4: =B4*E4 -> 0 | G4: =C4*E4 -> 0 | H4: =D4*E4 -> 0
A5: 4 | B5: =Pricing_Logic!C5 -> 0 | C5: =B5*1.05 -> 0 | D5: =B5*0.95 -> 0 | E5: =IF(Market_Input!I5="",0,Market_Input!I5*IF(Market_Input!J5="",1,Market_Input!J5)) -> 0 | F5: =B5*E5 -> 0 | G5: =C5*E5 -> 0 | H5: =D5*E5 -> 0
A6: 5 | B6: =Pricing_Logic!C6 -> 0 | C6: =B6*1.05 -> 0 | D6: =B6*0.95 -> 0 | E6: =IF(Market_Input!I6="",0,Market_Input!I6*IF(Market_Input!J6="",1,Market_Input!J6)) -> 0 | F6: =B6*E6 -> 0 | G6: =C6*E6 -> 0 | H6: =D6*E6 -> 0
A7: 6 | B7: =Pricing_Logic!C7 -> 0 | C7: =B7*1.05 -> 0 | D7: =B7*0.95 -> 0 | E7: =IF(Market_Input!I7="",0,Market_Input!I7*IF(Market_Input!J7="",1,Market_Input!J7)) -> 0 | F7: =B7*E7 -> 0 | G7: =C7*E7 -> 0 | H7: =D7*E7 -> 0
A8: 7 | B8: =Pricing_Logic!C8 -> 0 | C8: =B8*1.05 -> 0 | D8: =B8*0.95 -> 0 | E8: =IF(Market_Input!I8="",0,Market_Input!I8*IF(Market_Input!J8="",1,Market_Input!J8)) -> 0 | F8: =B8*E8 -> 0 | G8: =C8*E8 -> 0 | H8: =D8*E8 -> 0
A9: 8 | B9: =Pricing_Logic!C9 -> 0 | C9: =B9*1.05 -> 0 | D9: =B9*0.95 -> 0 | E9: =IF(Market_Input!I9="",0,Market_Input!I9*IF(Market_Input!J9="",1,Market_Input!J9)) -> 0 | F9: =B9*E9 -> 0 | G9: =C9*E9 -> 0 | H9: =D9*E9 -> 0
A10: 9 | B10: =Pricing_Logic!C10 -> 0 | C10: =B10*1.05 -> 0 | D10: =B10*0.95 -> 0 | E10: =IF(Market_Input!I10="",0,Market_Input!I10*IF(Market_Input!J10="",1,Market_Input!J10)) -> 0 | F10: =B10*E10 -> 0 | G10: =C10*E10 -> 0 | H10: =D10*E10 -> 0
A11: 10 | B11: =Pricing_Logic!C11 -> 0 | C11: =B11*1.05 -> 0 | D11: =B11*0.95 -> 0 | E11: =IF(Market_Input!I11="",0,Market_Input!I11*IF(Market_Input!J11="",1,Market_Input!J11)) -> 0 | F11: =B11*E11 -> 0 | G11: =C11*E11 -> 0 | H11: =D11*E11 -> 0
A12: 11 | B12: =Pricing_Logic!C12 -> 0 | C12: =B12*1.05 -> 0 | D12: =B12*0.95 -> 0 | E12: =IF(Market_Input!I12="",0,Market_Input!I12*IF(Market_Input!J12="",1,Market_Input!J12)) -> 0 | F12: =B12*E12 -> 0 | G12: =C12*E12 -> 0 | H12: =D12*E12 -> 0
A13: 12 | B13: =Pricing_Logic!C13 -> 0 | C13: =B13*1.05 -> 0 | D13: =B13*0.95 -> 0 | E13: =IF(Market_Input!I13="",0,Market_Input!I13*IF(Market_Input!J13="",1,Market_Input!J13)) -> 0 | F13: =B13*E13 -> 0 | G13: =C13*E13 -> 0 | H13: =D13*E13 -> 0
... A26: 25 | B26: =Pricing_Logic!C26 -> 0 | C26: =B26*1.05 -> 0 | D26: =B26*0.95 -> 0 | E26: =IF(Market_Input!I26="",0,Market_Input!I26*IF(Market_Input!J26="",1,Market_Input!J26)) -> 0 | F26: =B26*E26 -> 0 | G26: =C26*E26 -> 0 | H26: =D26*E26 -> 0

Sheet Outputs
A1: Product # | B1: Product Name | C1: Recommended (Local) | D1: Recommended (USD) | E1: Break-Even (Local) | F1: Break-Even (USD) | G1: Competitor Range | H1: Margin % | I1: Best Case | J1: Base Case | K1: Worst Case
A2: 1 | B2: =Product_Input!B2 -> 0 | C2: =IF(Pricing_Logic!C2+Pricing_Logic!E2=0,0,(Pricing_Logic!C2+Pricing_Logic!E2)/2) -> 0 | D2: =C2*FX_Rate -> 0 | E2: =Pricing_Logic!G2 -> 0 | F2: =Pricing_Logic!L2 -> 0 | G2: =IF(Market_Input!C2="","N/A",Market_Input!C2&" - "&Market_Input!D2) -> N/A | H2: =IF(C2=0,0,(C2-Pricing_Logic!B2)/C2) -> 0 | I2: =Scenarios!C2 -> 0 | J2: =Scenarios!B2 -> 0 | K2: =Scenarios!D2 -> 0
A3: 2 | B3: =Product_Input!B3 -> 0 | C3: =IF(Pricing_Logic!C3+Pricing_Logic!E3=0,0,(Pricing_Logic!C3+Pricing_Logic!E3)/2) -> 0 | D3: =C3*FX_Rate -> 0 | E3: =Pricing_Logic!G3 -> 0 | F3: =Pricing_Logic!L3 -> 0 | G3: =IF(Market_Input!C3="","N/A",Market_Input!C3&" - "&Market_Input!D3) -> N/A | H3: =IF(C3=0,0,(C3-Pricing_Logic!B3)/C3) -> 0 | I3: =Scenarios!C3 -> 0 | J3: =Scenarios!B3 -> 0 | K3: =Scenarios!D3 -> 0
A4: 3 | B4: =Product_Input!B4 -> 0 | C4: =IF(Pricing_Logic!C4+Pricing_Logic!E4=0,0,(Pricing_Logic!C4+Pricing_Logic!E4)/2) -> 0 | D4: =C4*FX_Rate -> 0 | E4: =Pricing_Logic!G4 -> 0 | F4: =Pricing_Logic!L4 -> 0 | G4: =IF(Market_Input!C4="","N/A",Market_Input!C4&" - "&Market_Input!D4) -> N/A | H4: =IF(C4=0,0,(C4-Pricing_Logic!B4)/C4) -> 0 | I4: =Scenarios!C4 -> 0 | J4: =Scenarios!B4 -> 0 | K4: =Scenarios!D4 -> 0
A5: 4 | B5: =Product_Input!B5 -> 0 | C5: =IF(Pricing_Logic!C5+Pricing_Logic!E5=0,0,(Pricing_Logic!C5+Pricing_Logic!E5)/2) -> 0 | D5: =C5*FX_Rate -> 0 | E5: =Pricing_Logic!G5 -> 0 | F5: =Pricing_Logic!L5 -> 0 | G5: =IF(Market_Input!C5="","N/A",Market_Input!C5&" - "&Market_Input!D5) -> N/A | H5: =IF(C5=0,0,(C5-Pricing_Logic!B5)/C5) -> 0 | I5: =Scenarios!C5 -> 0 | J5: =Scenarios!B5 -> 0 | K5: =Scenarios!D5 -> 0
A6: 5 | B6: =Product_Input!B6 -> 0 | C6: =IF(Pricing_Logic!C6+Pricing_Logic!E6=0,0,(Pricing_Logic!C6+Pricing_Logic!E6)/2) -> 0 | D6: =C6*FX_Rate -> 0 | E6: =Pricing_Logic!G6 -> 0 | F6: =Pricing_Logic!L6 -> 0 | G6: =IF(Market_Input!C6="","N/A",Market_Input!C6&" - "&Market_Input!D6) -> N/A | H6: =IF(C6=0,0,(C6-Pricing_Logic!B6)/C6) -> 0 | I6: =Scenarios!C6 -> 0 | J6: =Scenarios!B6 -> 0 | K6: =Scenarios!D6 -> 0
A7: 6 | B7: =Product_Input!B7 -> 0 | C7: =IF(Pricing_Logic!C7+Pricing_Logic!E7=0,0,(Pricing_Logic!C7+Pricing_Logic!E7)/2) -> 0 | D7: =C7*FX_Rate -> 0 | E7: =Pricing_Logic!G7 -> 0 | F7: =Pricing_Logic!L7 -> 0 | G7: =IF(Market_Input!C7="","N/A",Market_Input!C7&" - "&Market_Input!D7) -> N/A | H7: =IF(C7=0,0,(C7-Pricing_Logic!B7)/C7) -> 0 | I7: =Scenarios!C7 -> 0 | J7: =Scenarios!B7 -> 0 | K7: =Scenarios!D7 -> 0
A8: 7 | B8: =Product_Input!B8 -> 0 | C8: =IF(Pricing_Logic!C8+Pricing_Logic!E8=0,0,(Pricing_Logic!C8+Pricing_Logic!E8)/2) -> 0 | D8: =C8*FX_Rate -> 0 | E8: =Pricing_Logic!G8 -> 0 | F8: =Pricing_Logic!L8 -> 0 | G8: =IF(Market_Input!C8="","N/A",Market_Input!C8&" - "&Market_Input!D8) -> N/A | H8: =IF(C8=0,0,(C8-Pricing_Logic!B8)/C8) -> 0 | I8: =Scenarios!C8 -> 0 | J8: =Scenarios!B8 -> 0 | K8: =Scenarios!D8 -> 0
A9: 8 | B9: =Product_Input!B9 -> 0 | C9: =IF(Pricing_Logic!C9+Pricing_Logic!E9=0,0,(Pricing_Logic!C9+Pricing_Logic!E9)/2) -> 0 | D9: =C9*FX_Rate -> 0 | E9: =Pricing_Logic!G9 -> 0 | F9: =Pricing_Logic!L9 -> 0 | G9: =IF(Market_Input!C9="","N/A",Market_Input!C9&" - "&Market_Input!D9) -> N/A | H9: =IF(C9=0,0,(C9-Pricing_Logic!B9)/C9) -> 0 | I9: =Scenarios!C9 -> 0 | J9: =Scenarios!B9 -> 0 | K9: =Scenarios!D9 -> 0
A10: 9 | B10: =Product_Input!B10 -> 0 | C10: =IF(Pricing_Logic!C10+Pricing_Logic!E10=0,0,(Pricing_Logic!C10+Pricing_Logic!E10)/2) -> 0 | D10: =C10*FX_Rate -> 0 | E10: =Pricing_Logic!G10 -> 0 | F10: =Pricing_Logic!L10 -> 0 | G10: =IF(Market_Input!C10="","N/A",Market_Input!C10&" - "&Market_Input!D10) -> N/A | H10: =IF(C10=0,0,(C10-Pricing_Logic!B10)/C10) -> 0 | I10: =Scenarios!C10 -> 0 | J10: =Scenarios!B10 -> 0 | K10: =Scenarios!D10 -> 0
A11: 10 | B11: =Product_Input!B11 -> 0 | C11: =IF(Pricing_Logic!C11+Pricing_Logic!E11=0,0,(Pricing_Logic!C11+Pricing_Logic!E11)/2) -> 0 | D11: =C11*FX_Rate -> 0 | E11: =Pricing_Logic!G11 -> 0 | F11: =Pricing_Logic!L11 -> 0 | G11: =IF(Market_Input!C11="","N/A",Market_Input!C11&" - "&Market_Input!D11) -> N/A | H11: =IF(C11=0,0,(C11-Pricing_Logic!B11)/C11) -> 0 | I11: =Scenarios!C11 -> 0 | J11: =Scenarios!B11 -> 0 | K11: =Scenarios!D11 -> 0
A12: 11 | B12: =Product_Input!B12 -> 0 | C12: =IF(Pricing_Logic!C12+Pricing_Logic!E12=0,0,(Pricing_Logic!C12+Pricing_Logic!E12)/2) -> 0 | D12: =C12*FX_Rate -> 0 | E12: =Pricing_Logic!G12 -> 0 | F12: =Pricing_Logic!L12 -> 0 | G12: =IF(Market_Input!C12="","N/A",Market_Input!C12&" - "&Market_Input!D12) -> N/A | H12: =IF(C12=0,0,(C12-Pricing_Logic!B12)/C12) -> 0 | I12: =Scenarios!C12 -> 0 | J12: =Scenarios!B12 -> 0 | K12: =Scenarios!D12 -> 0
A13: 12 | B13: =Product_Input!B13 -> 0 | C13: =IF(Pricing_Logic!C13+Pricing_Logic!E13=0,0,(Pricing_Logic!C13+Pricing_Logic!E13)/2) -> 0 | D13: =C13*FX_Rate -> 0 | E13: =Pricing_Logic!G13 -> 0 | F13: =Pricing_Logic!L13 -> 0 | G13: =IF(Market_Input!C13="","N/A",Market_Input!C13&" - "&Market_Input!D13) -> N/A | H13: =IF(C13=0,0,(C13-Pricing_Logic!B13)/C13) -> 0 | I13: =Scenarios!C13 -> 0 | J13: =Scenarios!B13 -> 0 | K13: =Scenarios!D13 -> 0
... A26: 25 | B26: =Product_Input!B26 -> 0 | C26: =IF(Pricing_Logic!C26+Pricing_Logic!E26=0,0,(Pricing_Logic!C26+Pricing_Logic!E26)/2) -> 0 | D26: =C26*FX_Rate -> 0 | E26: =Pricing_Logic!G26 -> 0 | F26: =Pricing_Logic!L26 -> 0 | G26: =IF(Market_Input!C26="","N/A",Market_Input!C26&" - "&Market_Input!D26) -> N/A | H26: =IF(C26=0,0,(C26-Pricing_Logic!B26)/C26) -> 0 | I26: =Scenarios!C26 -> 0 | J26: =Scenarios!B26 -> 0 | K26: =Scenarios!D26 -> 0

Sheet Data_Audit
A1: =IF(COUNTIF(B6:B10,TRUE)>0,"❌ MODEL BLOCKED — FIX CRITICAL ERRORS",IF(COUNTIF(B14:B17,TRUE)>0,"⚠️ MODEL OK WITH WARNINGS","✅ MODEL READY")) -> ❌ MODEL BLOCKED — FIX CRITICAL ERRORS
A3: 🔴 CRITICAL ERRORS | B3: Status | C3: Count | E3: 📊 FX DIAGNOSTICS | F3: Value
A6: Missing_Currency | B6: =IF(Client_Info!B8="",TRUE,FALSE) -> TRUE | C6: =IF(B6,1,0) -> 1 | E6: FX Rate Count | F6: =COUNTA(FX_Rates!C2:C13) -> 0
A7: Missing_FX_Rate | B7: =IF(COUNTIF(FX_Rates!C2:C13,">0")=0,TRUE,FALSE) -> TRUE | C7: =IF(B7,1,0) -> 1 | E7: Missing FX Rates | F7: =12-COUNTA(FX_Rates!C2:C13) -> 12
A8: Missing_Product_Name | B8: =IF(COUNTBLANK(Product_Input!B2:B26)>0,TRUE,FALSE) -> TRUE | C8: =COUNTBLANK(Product_Input!B2:B26) -> 25 | E8: Unique Currencies | F8: =COUNTA(FX_Rates!A2:A13) -> 0
A9: Missing_COGS | B9: =IF(COUNTBLANK(Product_Input!F2:F26)>0,TRUE,FALSE) -> TRUE | C9: =COUNTBLANK(Product_Input!F2:F26) -> 25 | E9: Valuation Date Set | F9: =IF(FX_Rates!H1="","❌ NO","✅ YES") -> ❌ NO
A10: Negative_Recommended_Price | B10: =IF(COUNTIF(Outputs!C2:C26,"<0")>0,TRUE,FALSE) -> FALSE | C10: =COUNTIF(Outputs!C2:C26,"<0") -> 0 | E10: Prev Month End | F10: =IF(FX_Rates!H1="","N/A",EOMONTH(FX_Rates!H1,-1)) -> N/A
A12: 🟡 WARNINGS | B12: Status | C12: Count | E12: 📈 PRODUCT COMPLETENESS | F12: Score | G12: Status
A14: Margin_Out_Of_Range | B14: =IF(COUNTIFS(Product_Input!K2:K26,"<0")+COUNTIFS(Product_Input!K2:K26,">0.9")>0,TRUE,FALSE) -> FALSE | C14: =COUNTIFS(Product_Input!K2:K26,"<0")+COUNTIFS(Product_Input!K2:K26,">0.9") -> 0 | E14: Products with Name | F14: =25-COUNTBLANK(Product_Input!B2:B26) -> 0
A15: Inflation_Out_Of_Range | B15: =IF(COUNTIFS(Market_Input!E2:E26,">0.5")>0,TRUE,FALSE) -> FALSE | C15: =COUNTIFS(Market_Input!E2:E26,">0.5") -> 0 | E15: Products with COGS | F15: =25-COUNTBLANK(Product_Input!F2:F26) -> 0
A16: Competitor_Data_Missing | B16: =IF(COUNTBLANK(Market_Input!B2:B26)>0,TRUE,FALSE) -> TRUE | C16: =COUNTBLANK(Market_Input!B2:B26) -> 25 | E16: Products with Comp Price | F16: =25-COUNTBLANK(Market_Input!B2:B26) -> 0
A17: Seasonality_Zero | B17: =IF(COUNTIFS(Market_Input!J2:J26,"=0")>0,TRUE,FALSE) -> FALSE | C17: =COUNTIFS(Market_Input!J2:J26,"=0") -> 0 | E17: Overall Score % | F17: =ROUND(((F14+F15+F16)/(25*3))*100,1) -> 0 | G17: =IF(F17<50,"🔴 Red",IF(F17<90,"🟡 Yellow","🟢 Green")) -> 🔴 Red
A19: 📋 SUMMARY | B19: Count
A21: Total Critical Errors | B21: =COUNTIF(B6:B10,TRUE) -> 4
A22: Total Warnings | B22: =COUNTIF(B14:B17,TRUE) -> 1
A23: Total Issues | B23: =B21+B22 -> 5
A25: Product # | B25: Has Name | C25: Has COGS | D25: Has Margin | E25: Has Comp Price | F25: Has Units | G25: Has Season | H25: Status
A26: 1 | B26: =IF(Product_Input!B2<>"",TRUE,FALSE) -> FALSE | C26: =IF(Product_Input!F2<>"",TRUE,FALSE) -> FALSE | D26: =IF(Product_Input!K2<>"",TRUE,FALSE) -> FALSE | E26: =IF(Market_Input!B2<>"",TRUE,FALSE) -> FALSE | F26: =IF(Market_Input!I2<>"",TRUE,FALSE) -> FALSE | G26: =IF(Market_Input!J2<>"",TRUE,FALSE) -> FALSE | H26: =IF(AND(B26,C26,D26,E26,F26,G26),"✅ COMPLETE","❌ INCOMPLETE") -> ❌ INCOMPLETE
A27: 2 | B27: =IF(Product_Input!B3<>"",TRUE,FALSE) -> FALSE | C27: =IF(Product_Input!F3<>"",TRUE,FALSE) -> FALSE | D27: =IF(Product_Input!K3<>"",TRUE,FALSE) -> FALSE | E27: =IF(Market_Input!B3<>"",TRUE,FALSE) -> FALSE | F27: =IF(Market_Input!I3<>"",TRUE,FALSE) -> FALSE | G27: =IF(Market_Input!J3<>"",TRUE,FALSE) -> FALSE | H27: =IF(AND(B27,C27,D27,E27,F27,G27),"✅ COMPLETE","❌ INCOMPLETE") -> ❌ INCOMPLETE
A28: 3 | B28: =IF(Product_Input!B4<>"",TRUE,FALSE) -> FALSE | C28: =IF(Product_Input!F4<>"",TRUE,FALSE) -> FALSE | D28: =IF(Product_Input!K4<>"",TRUE,FALSE) -> FALSE | E28: =IF(Market_Input!B4<>"",TRUE,FALSE) -> FALSE | F28: =IF(Market_Input!I4<>"",TRUE,FALSE) -> FALSE | G28: =IF(Market_Input!J4<>"",TRUE,FALSE) -> FALSE | H28: =IF(AND(B28,C28,D28,E28,F28,G28),"✅ COMPLETE","❌ INCOMPLETE") -> ❌ INCOMPLETE
A29: 4 | B29: =IF(Product_Input!B5<>"",TRUE,FALSE) -> FALSE | C29: =IF(Product_Input!F5<>"",TRUE,FALSE) -> FALSE | D29: =IF(Product_Input!K5<>"",TRUE,FALSE) -> FALSE | E29: =IF(Market_Input!B5<>"",TRUE,FALSE) -> FALSE | F29: =IF(Market_Input!I5<>"",TRUE,FALSE) -> FALSE | G29: =IF(Market_Input!J5<>"",TRUE,FALSE) -> FALSE | H29: =IF(AND(B29,C29,D29,E29,F29,G29),"✅ COMPLETE","❌ INCOMPLETE") -> ❌ INCOMPLETE
A30: 5 | B30: =IF(Product_Input!B6<>"",TRUE,FALSE) -> FALSE | C30: =IF(Product_Input!F6<>"",TRUE,FALSE) -> FALSE | D30: =IF(Product_Input!K6<>"",TRUE,FALSE) -> FALSE | E30: =IF(Market_Input!B6<>"",TRUE,FALSE) -> FALSE | F30: =IF(Market_Input!I6<>"",TRUE,FALSE) -> FALSE | G30: =IF(Market_Input!J6<>"",TRUE,FALSE) -> FALSE | H30: =IF(AND(B30,C30,D30,E30,F30,G30),"✅ COMPLETE","❌ INCOMPLETE") -> ❌ INCOMPLETE
A31: 6 | B31: =IF(Product_Input!B7<>"",TRUE,FALSE) -> FALSE | C31: =IF(Product_Input!F7<>"",TRUE,FALSE) -> FALSE | D31: =IF(Product_Input!K7<>"",TRUE,FALSE) -> FALSE | E31: =IF(Market_Input!B7<>"",TRUE,FALSE) -> FALSE | F31: =IF(Market_Input!I7<>"",TRUE,FALSE) -> FALSE | G31: =IF(Market_Input!J7<>"",TRUE,FALSE) -> FALSE | H31: =IF(AND(B31,C31,D31,E31,F31,G31),"✅ COMPLETE","❌ INCOMPLETE") -> ❌ INCOMPLETE
A32: 7 | B32: =IF(Product_Input!B8<>"",TRUE,FALSE) -> FALSE | C32: =IF(Product_Input!F8<>"",TRUE,FALSE) -> FALSE | D32: =IF(Product_Input!K8<>"",TRUE,FALSE) -> FALSE | E32: =IF(Market_Input!B8<>"",TRUE,FALSE) -> FALSE | F32: =IF(Market_Input!I8<>"",TRUE,FALSE) -> FALSE | G32: =IF(Market_Input!J8<>"",TRUE,FALSE) -> FALSE | H32: =IF(AND(B32,C32,D32,E32,F32,G32),"✅ COMPLETE","❌ INCOMPLETE") -> ❌ INCOMPLETE
A33: 8 | B33: =IF(Product_Input!B9<>"",TRUE,FALSE) -> FALSE | C33: =IF(Product_Input!F9<>"",TRUE,FALSE) -> FALSE | D33: =IF(Product_Input!K9<>"",TRUE,FALSE) -> FALSE | E33: =IF(Market_Input!B9<>"",TRUE,FALSE) -> FALSE | F33: =IF(Market_Input!I9<>"",TRUE,FALSE) -> FALSE | G33: =IF(Market_Input!J9<>"",TRUE,FALSE) -> FALSE | H33: =IF(AND(B33,C33,D33,E33,F33,G33),"✅ COMPLETE","❌ INCOMPLETE") -> ❌ INCOMPLETE
A34: 9 | B34: =IF(Product_Input!B10<>"",TRUE,FALSE) -> FALSE | C34: =IF(Product_Input!F10<>"",TRUE,FALSE) -> FALSE | D34: =IF(Product_Input!K10<>"",TRUE,FALSE) -> FALSE | E34: =IF(Market_Input!B10<>"",TRUE,FALSE) -> FALSE | F34: =IF(Market_Input!I10<>"",TRUE,FALSE) -> FALSE | G34: =IF(Market_Input!J10<>"",TRUE,FALSE) -> FALSE | H34: =IF(AND(B34,C34,D34,E34,F34,G34),"✅ COMPLETE","❌ INCOMPLETE") -> ❌ INCOMPLETE
A35: 10 | B35: =IF(Product_Input!B11<>"",TRUE,FALSE) -> FALSE | C35: =IF(Product_Input!F11<>"",TRUE,FALSE) -> FALSE | D35: =IF(Product_Input!K11<>"",TRUE,FALSE) -> FALSE | E35: =IF(Market_Input!B11<>"",TRUE,FALSE) -> FALSE | F35: =IF(Market_Input!I11<>"",TRUE,FALSE) -> FALSE | G35: =IF(Market_Input!J11<>"",TRUE,FALSE) -> FALSE | H35: =IF(AND(B35,C35,D35,E35,F35,G35),"✅ COMPLETE","❌ INCOMPLETE") -> ❌ INCOMPLETE
A36: 11 | B36: =IF(Product_Input!B12<>"",TRUE,FALSE) -> FALSE | C36: =IF(Product_Input!F12<>"",TRUE,FALSE) -> FALSE | D36: =IF(Product_Input!K12<>"",TRUE,FALSE) -> FALSE | E36: =IF(Market_Input!B12<>"",TRUE,FALSE) -> FALSE | F36: =IF(Market_Input!I12<>"",TRUE,FALSE) -> FALSE | G36: =IF(Market_Input!J12<>"",TRUE,FALSE) -> FALSE | H36: =IF(AND(B36,C36,D36,E36,F36,G36),"✅ COMPLETE","❌ INCOMPLETE") -> ❌ INCOMPLETE
A37: 12 | B37: =IF(Product_Input!B13<>"",TRUE,FALSE) -> FALSE | C37: =IF(Product_Input!F13<>"",TRUE,FALSE) -> FALSE | D37: =IF(Product_Input!K13<>"",TRUE,FALSE) -> FALSE | E37: =IF(Market_Input!B13<>"",TRUE,FALSE) -> FALSE | F37: =IF(Market_Input!I13<>"",TRUE,FALSE) -> FALSE | G37: =IF(Market_Input!J13<>"",TRUE,FALSE) -> FALSE | H37: =IF(AND(B37,C37,D37,E37,F37,G37),"✅ COMPLETE","❌ INCOMPLETE") -> ❌ INCOMPLETE
... A50: 25 | B50: =IF(Product_Input!B26<>"",TRUE,FALSE) -> FALSE | C50: =IF(Product_Input!F26<>"",TRUE,FALSE) -> FALSE | D50: =IF(Product_Input!K26<>"",TRUE,FALSE) -> FALSE | E50: =IF(Market_Input!B26<>"",TRUE,FALSE) -> FALSE | F50: =IF(Market_Input!I26<>"",TRUE,FALSE) -> FALSE | G50: =IF(Market_Input!J26<>"",TRUE,FALSE) -> FALSE | H50: =IF(AND(B50,C50,D50,E50,F50,G50),"✅ COMPLETE","❌ INCOMPLETE") -> ❌ INCOMPLETE
